Workbook

Sheet ASWXL.Storage
A1: ASWXL Storage Version 40.0.0.10 | B1: C:\Program Files\AspenTech\Aspen Simulation Workbook V14.0
A2: UEsDBBQAAAAIALt1wlq3H+Sh4O8AAL3rCAAYAEIAQXNwZW5UZWNoLkFTV1hMLldvcmtib29rTlU2AE5VQ1gYAEEAcwBwAGUAbgBUAGUAYwBoAC4AQQBTAFcAWABMAC4AVwBvAHIAawBiAG8AbwBrAAoABAAAAAAA7L3ZeyPJdidWvdXtrnu71fde7StU7vFIoyaYEblT7NKAJKoINUFSBKure66uoSwwyYIKBCgs1c3rsT/vM57xeDyjkWfVzMjjfV/G8vruP8FPfvCD3/zi7/OnB7/IEbkhAZwEIpmRESAyq78GkcjIiBMnIn7nROQvTjx468GDB39K/tG/9N933iYff6E2unH7527nVbXWevHlUbV2cdHtf1r5wh2OuoP+Z5pSpf8h5dPK/qQ3ngzdz/ruZDx0ep9WTicve93O5+7t+eC12/9McTodXe0oln2JFevi8j1a0E/P5/9iMHz9cjB4/X1y8532m8532qPu9aTnjElpo++2nc64+8ZtRT99p30zdC/dodvvuKPvtLv97rjr9Lo/ci8+al87o7E7PHDGTssd/+TsZTWowE/Eft4f9MfDQa/nDj9sD53+ldt0+s6VO/xO+2o4mNzUOqSI0ffbzmQ8uCaFd86dq+c3F87Y/YX2gdtzx+6587Lnvnjl9r3Lbv/qjObyZ9oTL1X9m47bezrpd7yq0GQnpOphfX+2PXLeuEfd/mv3glTvhOTh1ZU8+PPerfr1S/fiYuHmL7UvB8OO+3TS6525l0N39Oqkfzbp7w+ub6hIF1RlVO6nrkNbp+nc/GR7TOXc6zn91/uDHq212x+PfrbtjL72alDzJDx1+m69T68v3iX/HpD/yKf37913Hjyeb7cvnGGXJt6nCvQyoN1Hn082vT3yf5k25eyTv7zQ8VoN+v80PU31yXyq06g3zGb31i/Op6Qt7n+l32ia939leZpp/6Cpf34+8Vmsy9AEPzef4Nm0F3kief8qC/Wcay6a9I/fad2SXno9o75nbt8ddjvVg673gzO8/R38gx8ECVvjIel/n1auR53BsNd9GRux3oBlGK8vTdPRO7qBbFVzyaj94ac/SCtFoz9WcU5CnLz8XSID38x/yDm7t2jjffAO/aBD54P36MdD2vYffIt+0sv36ccH5OO9PyHgu6zT0OTfeuP0Jm67/eB9mjXNmfQjktEH36bZfIdevkd/ZRyfD9vOcOjcPmx3BpP++N3FPtsIn/vBD70h4lXow8BCvPdupiE+X/gvLBQ+fTJe/EeB6t57jwknqjRp+2rSvXivfexcu98haD3qDLs39OZ322+6oy4FvXFr7AzHk5vvtntd0sH654Mm0TkZzKPvtd03BCGPBlctYliOutfd8bsEQ69IysGVB5/fjP3x9m0/ZY1W6yfbL5zueH8yHA2GFOwJKPdJkp9tP+1NRq+m4gWlkNy/3SYy7lNduMOP2kfELrUGvTfueffa/V67FuB9JOeHbZJjdPV+m+S474zcnw6szcGECnRw23euux2ScvRT7Qv/wrdZT4fu700ITt5+f/b358SCjj7yPls3bufUGb9Sfiy6/IL2PmX2Npq7jWZv47nbePa2Ondbnb2tzd3WZm/rc7f12dvG3G1j9rY5d9ucvW3N3bZmb9tzt2PXnlqUj+f0oswlQPMJ0FwCPJ8gpjuvn7zz1lseAIR2OTQq4L8H3w6Q8xnpZm+99f7WsoFbp/046Jped/Yt1vsfvvXWArTQERcb46QTeokfeqP13f+HoFq8ZApUb7edt9sv32533m5fvN12325fvt2+erv96u129+32777dfv1g+u/9b33r7eDfX/onrz79sd96tveHf+H/+oM/+u6fPHz4Mbmvnd4So3w76o7avznou6O2bqL2193xq8Fk/HQ46Nc7g/6AdO9R+2j/5MoZDXrdvvvwu17eb/2/RH8Pv0dBxavUKRmaD6nn+QnuGJajWuaWjpTLLQ1r5pZ9oTtbrm7rDkLo0lCMD37c08n//qsPHvx/xo/e+T//6P/4yySjnwjQyfv3AS3n4U+RD3w+uKk6NzfNwYXbqxIPdHJDjbTrXG+dEvvpElt5MxlXT88a+/WqioxntdbDn6YQ/8l27+HPkC8vZjPo/ogM74rTv6jsD0bU16zWv3E7E887nlxfEztcbRx/UW+dN+vH5zvV88HY6VVOhwNqNCv7zk2XXtNHH/4sLeV56+Dhz6UWExut2tOHPx+K+QvkSyuTmASZu0P3onJGkKgyuKycEQGG/Ye/SDL+8NQlfm5/vP1nv3Kd4cNfIj+d8lHJxYSopOX03NHDCu1wRBfbXhm/TK7UVWUcEIE7Y3rlFUKHwMPHoUr/mcUcVqhUNQ4a9dbDT0Kd/hny5bc41JPMNYYOTew3+j87U9E/S65+M1Mhj0+rJ9UKaaLu4OLxw1+hA9/LmYyNB885iH/mfF1pkk5BnJHeyK/Cn5upwq+RK3umoDN3RBy2USXM9Pm42+uOb7fIdfVkMqY6Pz85f36+f9I6f/gplfiT7VfDh1sUU1ZJHAyg2Vavhq2+zanNfIm7blBhJV5h6oO995B1CkS9zUdHA+fiKZk3DobfCnzb9+k00Rm6w48PndGrfSIqGQ5vuhfu8H36A3V33iXu7eihZ35GpHrvEK/r2+//PDARaIR5fQLdXMif2ob/+7es36BD+9EjCpMfIPqBab2ouCsmbNTJ/alwMn/mXg+oUoNqffDlda/VeeVeO98m3w66l5fPhs41MZYfBaIF6TxvUqUIrZGP/+3339n9jW+ue5U3geP/GFWVxxWiyMEFyfuzx5Px5RYyHv/Gkw8f7X4z2hl5JVS6F589jqR6XCHu2JU7pn7m6MbpuJ89fjUe3+xsb5Nib4hLVh0Mr7ZpypE7RtVvRhePK6TI/mjnejTuj1hTM+f6zTTp119/Xf1a9VJiRUHbXzaPfB1NJSD+n0OqOewHdRttEbs5HIwGl+OtzuB6h6Tb8lNNn7kZDm5WP0NTPa44Y+Ilv5wQ53MwvD5wLx0yPj97/HsTp9e97LpEaLfnXhOIT7hN9F6pUM0HySrEbXVnlO8Lt9MYBR3js8fj4cSNfn8+cok/PvR8+Q7B++C2l6+fc8dbNvnm/PbGDX4Nfn81IEhdue72Tzod4tJ/9pj0jGvnm/Bq0n9J/LGLUMjpg7OinjtX4XyKCkW1shPrbTj+dLJA07sj34efvwUV3TiI1HDmOhcn/d7tnHZqk/Gg0e8MvafCe2NS8GePSW7d/jhKmb6PbzNISPOLFTjyZlQ5lxmbCfIserafsAjiAWxMhIvBJOgkwkTwphZytfBbdKyPb+UK4a24yBXBW0oU2Ba720lg4t2BQci7FcjNgHrnSainFBr11gaBvD4nVwTiJB6SVnKHZ4OvY5K8HAx6rkPUcxH6BJdkEiAWHIlosZZaP/loN6ZukzOW24R7gyFpv9qQekPcxtHd1PGiezF+tWbN5IFga3zbkzzSzrvjtZCDDndS5hpI0uj33aHfeyX226ZLyqj1L/Zd+hIA6rwChWmNnfEE8kKiAXTy+f13SY66o3GOHohXBnVDBPoU+6+6vQvBZRKTeHJ5SZ4RNHpy7x+1cLGi0O7pVAtS0Xl/0Jtc9yUCc2CoJNuoq/5g6F6so0/DEW3uYqhm3QfR5e+RpwW7MPnCn/fSolypTJKQ90pl+h63NqsG8+uWEkQI1i2DTtp0bg+dN+6JpxuSyflQtnxHg69nXHkZKrq5kS3CGqyqUmiSKwFl9ciVYMrTWYPVRslvG7yBud9zrm+iYvcdDzeCe5Xg5lq5W95YTpDau7eWUu8P+hfR2515senNLv3qXlTW4hUQFSiwbMtkXQPjF3pIS5t7xnkSMrK6dGtBoCjJC9LOqDv1Dk6H3cGQdK/PHm9hpJmapRqaFd2duptPwwHi/R45E62x079whhcBOWH0aSX4dti9uHAl19QnxPtGbr7X+vcq4c1UujgPes+9U4XvpieoIry56aoIZ3GwMsK7eapD8prJAUrsA8G9DawzXlJnvKF1VpfUWS3CUG8caEtUoBVDBfoSFejFUIGxRAVGEVRw5Lx0e0WoKN185nT7dG1nAyE9ql0bdmqj+3n6tZKXa4JX8BtYtUCKIgzTg+7opufcwi54cLMwE5LJ4Lo98CUFFrD63THd99V0ndFk6FZOpgk3XS/7Tr9dp6yfduMCwDqnX/HuVvzXYxu/muFxWNreLldAG/RmJbq58co46JKLkbeWVoDaUhBoexRbEB6COxuvhqn7s++M3avBEF45D1ygeJqNV423qNs+SbIi3u072477qJDIeCyxHIVQxKEzanvWYej2F3VB7lbidzdeHY1Rz3UuFxXRGFWOghsbrwPfk2hcLAEM359oHGwuaOROlw3f25a8sPx2sObbiPVviJHoO738WzJvPa3ooptAUA8ZmuWuSlDCteFHlrsqV4i21rsqn/a6N8GWvbmtUOsgXbnns9zzWe75LPd8lns+07tM5a7Pctcn3EPKfZ/lvs9y32e577OI+z7PnSvsgSC0olDsPZ9+xIiYnNHiMblTiXjUUsdD86KXIKPXqGsiJdEXzIShiuS9NHgnJcLi+TqUL6B/KMeifMFhHeu1E8gbNuBGKn/YSI966I0ZUMBwzEjf40XPmQn3OC/qcA3CNhIdJgjo63ANRCz3H+YjabC5Hd4+6x2VITmoqb/zHd4ouwbyrd6D7Anp7+mFwX2t9h6vk7Q08LcfCF1uGyfEHYiM8ozXLfbNlGRUJjVvehxwqc3jXC2sYckRg74Lk2zJaTcUK4agGW25rFcu65XLeuWyXqGX9Uq2EChhyRYq2UIlH6fk45R8nJKPU/JxYuII9EpKQk5JyEmYCQhxTWX7oD7sSV6PezroS/ZdjifXL93hOnhRL4bOzbn7zViyAWhQI9QdDPcHvYHkEL60dwgWI1948cdcgUDmqNtfB4/zhdu9eiV5eHsdudG/cL/ZlN7sL6oWqDeX1qq0Vst7x0ZZq9Ph4LLbc2d3fpbLtuWy7fov23oEsLWUbK0XlIl8Z+cL70rXQbLjwckl0ddI4jLdeffa9czNG6cnmblBJFkDimP5+qF8/VC+fihfP5SvH1K70yU5LKYRqdyfkqA2g4olQa0kqBWAoNbquH1n2B2UaxrlmsbM9LdxsudQr2wt5+blgssdJKPYtU/+p1mtpYBrvSK03gHJ1mBVqFwEKRdBykWQchGEq7vvvHH3BzfLz1gVP4akrs2ALqM7IsWMj6l5XzfTdOZ2iUvUdXrdH7lrJlrT6QwHe+4lmWq33HGjfzMZj2qdcfcNFJOCpq34iSskdcVPXgnTL6mY8NAfsXqdTfpMNSLp1rcqtUsCRStr4qVa74rM9TVaIntP81MvwZx+rfUinM+354qS2P8Yakkb7S7VI8/J643L6jXti+mqFeYt3MoeDTrOODjmaLZC9G5lelsq6Suwb/MiHlfmDZ/nNUU6RrlJKWZxrnxJEteG1AVo//UEVbdkykH5tmZ93taIfS+SM+a4N87QGQ+Go0b/cpAj4DwbDiY3pDS5TXfgdrrXTk+oHPwa0E//atCN8knIgVZ80u+SIoN6e9EqP3enIdlOh0QPw1vyUwDt00I8aXtuh3SKyjc3zvjVZ4+r29vXo3F/tOMH5+z60Q22Z5657Lq9i/ABPzUdI9txSX2ZkoSMZU61vz/ok5Zx6NjKQzjfU0shXtjmRGeYjx7P89Ej8TC/PKLSEqn09AJ5G0RXCxWh4MqU0fbMuykbcVB2zH7mqW0tq6gh5zynERaXlYdaoxiOOUABzZuOUYpaOQiUevjHdWdm1d38EWA5y2vw6pcCEMu6i0hrgVkzo0vhovIccSuKCkAEi80G7w4GYWjF3ASlyuArrAj1en2Or9g5jcLFOBGpsHc+xoTs4ei94+Oi+OBtIW99x3ZFcxEzvsuau7CxTa9chI1vouUuLLSDrw0bxOks45i/2QR3EuZa2wjR2gnWaFl9sxstmOvNvcYzNEYZDTvLo8ytfpJbc3FBmkdNX7u3Q/cSakmgPJLSHS5v8PzqsmCfvAr58idVaGYGl1yh2VljflWIr6KnqEXMlMx19UD+BduVz7iZZXfdtRkSUClDU9wV52I7P1JUBjIjy+vEYADzrehdhk7MJVheuwVfJN+6zDkp6YYP7AJkG0V3dCvuPJhmnXvI1Q/qA016RM4f0tVldTVyrwE8r2HuXPMzwmzdKvX8kneHWhzpHDqUQNRaUpE7QtadapEer2JvTmILOYHo0bsj/itB07Pe7mraF8W9izlPI/P07Lc7yOx1MAY/hNU8i+7hfHu3gJ69qPjZJeOsus+6AJ22v7NVgbXf36UKGU0WV0dIpAcUvKpZeHMDqB/l9hYIesXFjO+elhYH78x7bWa8FGtWeRpUEaY09GvAkXo3hQtAmlk3AJQ9vTMgFl5miBWZ3WGx0DLDXwFgxcyFB7MST+aoSD6dqfPKvXaePNQfPHjwT//WT+1edC8vr4Y7/h/nuvLNdY9k7a8+fvZ4MuwHT4y2rrud4WA0uBxvdQbXOyTdlp/qcfCMn8WqZ8KCtt4QrN2NlOTnsZqx9WR3xqhWAvG7F3PWdsqRGA6+PqEN7DG8guSvnNH+K+9wt88ed/sjdzh2adaNgyfK7jb53KVrsk8ax1/UW+fN+vH5TvV8MHZ6FTJ9v5h0xpWW03NHu9teql3viEnSBrvejmL6xeNznblOb3fb+7p7Slrtyfngpurc3HhiVlvdH3X7VxWnf1HZH4zG5Hu1/o3bmdD9EK3JNV3zra4s38t2t9W9nvQ80veT09vhoHc76o7avznou6O2bqL2193xq8Fk/HQ46Nc7g/6ANMmofbR/cuWMBr1u393djmWw6x9594TK9Mt75u52cL07PYTxibf9Z3c79svu9NDD8G7sl93YwaJPjgdjulVidzv+4250mCfVXshqDrOKrnePuv3X0eGeT54NBhdEjJnfdk9e/i4ZWp7WQZXF7gdp55s6TBM27pTWBuc4k4J0ITSbGf2B/IqfzDcvvYXpLfXJYmegN1V6U6MaaRzo/h+D/jlyXro9WBb/1u5Bd3TTc26TZY4n2N13+u063UNIO//0YvfQGbU9TB+6fXpr5nq3Meq5zqU3Xvxvu9szA5B1oGJgoCKGgYpiA/WkWjmlMVUvHgsdk49Pq/GS8x6NSLnXw3GqqIQxeLJk5E0fXhxuJ7FB9vg0NqzmxqE/nsBxqHljLGEc6nMjL9bq4Iibub9GI00FRhpmGGk4wSQeuKPu0L2onDljtzK4rJy5Y2L6hY7AJBHyHor2vR6JSVrLZBuTMpVkHpPEAcZrUtI1GroaMHRVhqGrLvVmT0hPdKg6PbVKcGfnBch72Or3etjCOuPg0M5nKdWjnRcm0aWdT7hGw1UHhqvGMFy1pcP1+bhLelfXHckarvMC5D1crQ0YrvM64zBc57OUOlznhUkcrvMJ12i4GsBw1RmGq75qrYg2Y2XfuenSa0mDFhYj76GrbcDQhTXHZwEJyFj2OhIg0rLlJCD5Gg1pExjSBsOQNmJDGhhvB2Si0BnTK0/5tOPwHtJgEbkvLeF7PV5BnSUMVGiMJE9qoYwXByo87vzx6g841f+TPF2FCoLmqlA6fuMOZR13FjDuTIZxZy41pWfO15WmQ4/NIv1EliGFhMh7XBr3elgm642DEYWylWpCIYESDSiUeI3Mpw0MY4thGFvLzWfgLuRqP+Eycjeg6F6PVFhpPCwonHMeJhQuCRiBcMI1MqKx7V/T4WczDD87PvzcMdXiqOpGXdnxoi3ODDgqrP/FH270tLArd7hkxCVnm98Y884w84tpvXLd8S/X8E4jB5fVHybwcKOaml5wG3mLakwadYHil4y1xbyAcRZlk250LeYNjKzFRLOjio6U9v5g0h974yp2KWpkQbQgxMILQgo4tgbOZDwYOfxGVSzD3MaT16r3eMjEdJRhsMRy4ThMYrlCAyR2e92GBkjEYWLixKk4p1+dnTSOq/UvT89wOCZix0VQxVZuBt3+uDIYVvx4bZU3njtzSX5o3bidivvNzdAdjUjqasXbJe30x5/S5E8Hw/HQ6ccSVLr9CjEN1yP63vZpb/D1iJoHkuGQ/NKvHLiXZAhUtqMnvdujauWMHq6+1el1O68r40HF52NWIh1RwuunlfErt1+ZjIjKhs7VFvFMti6GgxuavjO4uaWFeKlHNHwpKeYiVmJQDmnkWNUDbLBVq2poGNmaaSq6MYsU9HzqZJiIakhdpRMv15HHgbjqb1HVVQPte5GEwzYQaZbNnUYOnMGlGLOgzhwQJ6biRMjxVb8EcILmWMAaH0MY8SXIJIAWIu3YIa0zjEqf/jK92fbrUG81nh1vtU7r+7Fk/r1dP07+E1rB7mXXJcoIfplBr6Bw2FNuNy5mnGV6vRTWpjLsk4nw1WB4myRjdD/mlyMZfjnEoEIsFCoU51Cdb6lIqR63zmvP6hBEHk+uX7pDimgE+khmnxKU6/QmNHoqQZ7+hUuz9mZKQ/floNtzhzDQqEqELd64o0Qu/4s/9p7Y5F8w6lgdlb3eoPN6VPWr4MNMWBGROGPtNOCXwzRERiLM+DfvhDJUlzkAi6/OREzx1LwEUkLVZ8OUMJcFUAmKT8aUs9rB07NaOjzxQ317fc/vf+EvM1ATypQf1uwdnex/vpYoA5G9EAvbC6kLKPO0Xj9oJyLNU5d4LR7IVPoe6MBAguaBBM0BiYqyw8hU0ir5cQuJBRR7pwFzOvMCFLSWgBLvLouToqBd0s2IgofEgEsMLYJyiwggEP0MsfDPkLYAIHu1VqPVPjuD4OPMvexNvqlQFt6g8ivTK5dqfdzt9Sihll7/auXrV93OKzJxo34MmTFdDl238jV9/+FN+5xer9KhB0PQFO7NmCQnUy8yNLoXldNX9MZnXzg3g+HWUff3Jt2Lrafk8Rf06Vr/tkXhC8YtrYo0XdUNFZnqPILVt5A+h2JIif7NwtnydxAAlk2VJhLDkLLTSNgjkheKzWqYF57tOUQ/T5onRwSF/O8cIW7aNtm8pmk+Qv0mVP81VU9wmqYiSUE9r6nawbLEk2at1XpE2/BR6/zgi5OjR0FbRglkoyTE+kMstD+kz6IkFjGZQ0aekzksczKHEMEt+P1pbt5XPutEq6EJy53O4XI6JxxnICoiYuEiImMBZ/hM59AslHikCw838N3ncRiax2HBy88IEySB3wvnhiT5vOPKiCQr5nEYp57FYWjVORdEic/hcK7LzeuLGRCNErHwKJG5gBn3eQaHqopt6siwsYZEzOCw5BmcSvBLFYtfMxpelxncUnATM4PLzVUqZ3C8UBJiqSIWmiqyZlFSFTKDs/KcwalSZ3AawS14y1duuGVJ8rtUuTM4tZzBicYZDNFxEQsfF9kLOMNlBmfmMIFToQkc7W1CgUQnQAJHacgLSMx1xJEV8zdVST1/o4+IwZP4/I3mXkTEgGjGmIVmjJUFxLjP8zelauqqZSPbsjUhr+BUyRM4g+AXvGkvL/yaU/G6zOCWwpuYGVxurlI5g+OFkxDnHLNwznGcc+6HFrndak2uq+cn58/P909a53MbMmzLqGJFM3GEQt4+wyefbL8i7pH/nQVqztwRafNRJdwnHC/7ZDKm0BMTIedthwHe/PoiEKnEkVJzCHe1fE4WU3IOPtWc6hPRJ9Yky3YRT1spGwjFMlpAoefnjaOt1vNms3b21VJydu28lohE+06vQ5s/ycuKCTCDOZPBdXsQDPRPti+c20e0s5OP626ffJLx1CF/BqSht25dh97wf/nadV+TP95vr/0HX3tPvo6nfh2kaDb9JPTv9C69ol92t+NSZIDBg+6126dbPp7Qmm6d1c69yWj4ozea22eDr58gOumKrkCW+ZyyIa9RxrZPDAboZIrQGaeXq9ho1Z5WW+dnzfbz09NZHFSqSDd1ZNk6nt14smKf9XjoOtejapB3AHRhEdUvjoh9eXpWbTa+rB9Q/KsdVWtnza2a4E2hdFeo6G2hMxrNAfUC1Seind8kS4Bu2hEWZ5JBw8VCI3hNGIuH4DVmLHpu0KxhyNwFNAzuLyBhKGYyBjbJkD5r0MLuiINB0fn5XUST9VpzLaED4oxjFs44VpmhQwBg7AkGDJUABvy+LUfAKApM7K2AiT15MLFXUJiAmOGYhRmONXYPQ1GxiRXVMMycEaNxfFA7bgmGDI1ARg7RDVf4GHGdbj56hA2bCB9hAhn4EZZdSACBSNOYhTSNdVYAUauKRTq6pqv1LUXPH0Lqx3XRGKITDBG9ODOv1kKgiN+2y2DETyEJR/zCCwkkECsas7CiscEKJFpVVxC2dNMkPT5vX+S4dnp4fki7g1AkMQiS5BAkcsWmr1m9bj6STBs3EUqmSWRgybT0QoIJRJfGLHRpbLKCCapixUSmamv1LWTkDCanh/Xj2vH5oWAwMQmYiA7fM6/XzQeTaeMmgsk0iQwwmZZeSDCBWMWYhVWMrRRrJIpi27ql6YaFBIDJyZHoKY5FsCSH81tWLZPMqLUYWOK17VIo8VLIQhKv8CICiQrRhjELbRjb7F6JiVVTVU3sk+nyBZKTo6+2amdNwUhiEyTJ4bzFFV7JrF4LgCRR4yZDSZRECpZEpRcSTCBGscrCKFYVVjCxqtiwdRvReT3O+23v6Vdn4hdeVWWnocIRcvLDknm1FgBLwrZNhpIwhRQkCQsvJJBAlFuVhXKrIuaFV7Wq27at6Poc2bb5m9uvr9KwbVcAy9HhF80WMdBxZBGKKE2881w04SyuXV5YErD9a60WxPbPFV7CNmTHlyVEXFnrr0HRifTbvfFku/fyUcfpbV9dP3pG/76+ekRHw6PXwcVr76oZpGz6V9FlM0zWbJ52vJ/8Pznwa2kv2Kof0+XkU5hiqykrGLZrDH8Qx1Zl4diqKTi2pqUgC2kaz3Xi1rOtM3k4p+48F86Ti6vxvjlNtLU2DtGK4iJBZFqVhUyrMpNpcVXDKunals154Yai99Ozljyk0Haei6bHzSvzvoFF0GYlXtxTvIBYtSoLq1ZlZtWiuZnU/uwsqjYcOrd3xowDy9hCeUZ6uOcHTuU6+EPlpzwvOHiK61CfOWg4KCBxSrP/6Omjzx+d3XkCghInIOf15mn9rHb+/Cxhix/d45Xv/APldbCqChFoVRYCrQoQaH3DQTexc96oE2YcuBEvaJfJ0414OvzRqZxTHTkuyOa8iDJtbMCDCP2FwH8IGiz0H1aASZBahtsQFF1ItwGiwKosFFgVoMCKgoLDXEP6Bjig7jTu8a68NcKBQ8wMAodQgF8BCHCYa4jfNR7+EGlVZSGtqgBpVdTwPxEx/LWdhvAddhs5/E/Yh/+JpOF/UtThD9FMVRaaqQrQTEUN/2MRw1/faYjeHLeZw/+YffgfSxr+xwUd/hpEDlVZyKEqQA4VNfxrIhYBjJ2G6B1tmzn8a+wrADVJ0/9aQef+GkTn1FjonBpA5xQ1/PdPBAx/CUfIb+bwp63FOPxpUhnDn5ZbyOEPkTA1FhKmBpAwxQ1/Ed5/4tHu5fhPO/7Z3f99WdP//aLO/zWIiKixEBE1gIgoCgKa9fPD2nGup8sEMJB4IHsJA+lgIGoyRiiI0suAg6jwQkICxDvUWHiHGsA7FAUJwhBhyfHmJSakw4SUkCATEQoNCBCxUGMhFmoAsVAUIJyenZwKQoTkg8NLREiHCFGjMUJClF7KBs6w8EKCAsQg1FgYhJpEBuHx1t7zc0GokHwIeIkKKV8gRq3G+hoxekDKy8So9EICA8Qn1Fj4hJpEPiHx7+piYCH5bO0SFlJPH+rppg91idOHemEBAWIYaiwMQ00iw5A6d4IQIfnU6hIR0k8f0kBClF7W9KG4oADxDjUW3qEmkXeIqGcnCBWSj6AuUSEdKkxbjREWpg/IwIVp6UUEBh1iJGosjERNIiOxJYSTsORY5xIT0mFCKwUroSWLldAqKitBh3iJOgsvUZfISzwWAwImAYGSmshlXTEFCBzLAoHjwoIAxE7UWdiJOjM7Ua0iSzWQrmh8Dvma36iw3zjINbZsiAkWwQTRdMV53W0gQATtx7p7wU8tZQODX3QhYQJiMOosDEadmcGIqraGTd2w6lt0pY43Shwd1A+/OhCyqmAToBAfxX5Ge5uIE1ELskJF9IAUtIhKLyRgQPxGnYXfqDPzG7WqYiqqqRkoF7/i8/r5Sc5R68NQSMpOA4tmO85rbwMRI2pBRsCI0svAi6jwQsIFxH7UWdiPOjP70ajaqqIaikojh3I4iGvBwdg/Ocz57K0QLxDBC9FcyHn1bSBeTJuQ2cMIH5DjYYSlFxIyIG6kzsKN1Jm5kUbVMolbjQ16NBTmDhnPntcatf2TXIM2h5BBwy2KJkrOq28DIWPahIyQMX1ABmRMSy8kZECsSZ2FNakzsyaNqmEamolNMhHH/CclrefPjpovRACGSgBDNIVyXnkbCBhhA7K+Fg2SS3kzGpRdSKiA+JQ6C59Sl8inJC12KAYdNIIOJZ2SEyAcpgOEQ4mAcFhYQIC4lDoLl1Jn5lKqVUXVFNNSVWL+LP7bL748JxfnIuBBJ/Agmlc5r70NxIqoBVl3Y4TppWzHCAsvIlwYEMNSZ2FY6swMS1S1LctSLWzXt1T+zsRRg7p/WzUReGEQvBDNuZxX3wbixbQJGQFj+oAMxJiWXkjIgPiYBgsf02DmY6pVzdA1rGCtvkU3SOYDGXsiIMMkkCGaoTmvvs2FjL20kLEnFTL2CgoZEHvTYGFvGhJjS5I2OxTlWFgEJcoQk5yA4TCtL3Eo1Zc4LLAvAfE1DRa+piEx4mTQZkLcB5sAQxl0kiMwpPIYDqV6DIcF9hggXqbBwss02ONOVhUFkRSaqppGDtGl9k+apyIOplN2GqrwGJSzuttAuAjbjznKlJ9cTowpv+xCAgXEyDRYGJkGMyMTVVUbG6apGrls+WgJQwpEkEI0H3NeeRsIFa10UNGSCBWtIkMFxMQ0WJiYhsQolSKI2iomwFCGp+SCBewwIAkBCjr4IU6lwcKpNCRGotwXMfjpydZlEEoux9uwH24j6Wibgg5+iCVpsLAkDYksyVrrUMTw18jwLymSXPZl0QZj3ZJF00rZjUULLiQIQMxIg4UZaUiMMtmqHR+IQAGdoEAZYZLLDMBrMdZJgJdYyjzAK7mIQGBCnEeDhfNopOA8GqpmY0VXc4sltdU4FsGRVg2CDOI5j7Pq20CYmDZhiohS/gOygkr5pRcSMiDOo8nCeTSZOY+oahqqZXgL5Qr/95H7Z3vHoiDDJJAhmvM4r74NhIxpE7KuMkQPSFlsiEovJGRAnEeThfNoyuQ8PjtsikIJi6BEyXnkQm2KWo2V2hQ9IIXaFJVeSGCAOI8mC+fRlMh5bD2jLSaEDK3aBBhKziOXtYio1VjXI6IHpKxJRKUXEhggzqPJwnk0JZ61HbSZCDK0puw0NOFMx00GBnYy9PQBicBQUDK0CXEcTRaOo8nMcdRoSCMTY82sb6EcUGJ/67R2RntJ/iiBCEqIZjnOq28TISNqQlbIiB6QAhlR6YWEDIjraLJwHU12rmNVwZauIt1S+AeBaQoEDEwAQzj7cUZ5GwgXzbRw0ZQKF81iwwXEjjRZ2JEmMzsSVW3bVpCeUxj8xtbp2VMh6xOaSvBCNGFyXnsbiBhRCzICRpReBl5EhRcSLiA+pcnCpzTZ+ZRVpJo2ti07L6wQsmShEawQzq6Mq25jgYJ97SJKLw8oirpyAXEuTRbOpcnOuawqKjKwopoK/9My9r/a18U4FToBCuEEzBnVbSBShM3HypcIkkthSwRlFxEmLIiRabIwMk32c76rCGkIW2oOB2R4bSfEnTAISgg/9DuuuU0FCXZvIkwuDSQK6ktYEAfTYuFgWswcTL2qq5ama8gis2wzD5wwxHgTJsEJ0QzMeeVtJlQY6fwJQ6I/YRTWn4C4lxYL99Ji515WFdMydMPAZi7TDkOMQ2ERoBBOwpxR3abCRCqPwpDoURiF9SggJqbFwsS0mJmYatW2dNuwNTuXtx57DdKARycigsRoNoEK0bTMefVtIFhMm5ARLqYPyACMaemFhAyIo2mxcDStNHEpNVUzVduw+AebI41nnh49FwEYurLT0CUEpowpbwPhYtqA7N5F8IAk/yIovZBwATE3LRbmpsXM3FSqyLQ0pGoq/4MyamdNIesVOiJQIZqzOaO4DUSKoPFYt5f7qaXsLfeLLiRAQDxNi4WnaUmMSUkbTMTqhI4JLJRxKXmBAfuKRJBaFhgUdT0CYmFaLCxMKwUL01SQaZoaPRqKf5SJ08P6ce34XETgOl0l4CCehjmrvg1EimkTMoLF9AEZeDEtvZCQATExLRYmpsXMxERVbGBDV23a523+kPHVWf24LmRBQiOIIZqMOa+9TUSMsAVZASNMLwUvwsILCRcQH9Ni4WNazHxMvWqrhqEhHeeyk/SgcSrqvAxdJ3ghmpM5r74NxItpEzICxvQBGYgxLb2IkGFD3EyLhZtppeBmKpqCbWSZOn8uReP4oHYsxL0wCFyIJ2fGVbeBYBE2H+tejyC5lK0eQdmFhAmInWmzsDNtZnamRvdMY023rXx2kB4fiJqImAQpRNMz57W3mViRaiISpZeEFsWdiNgQQ9NmYWjazAxNrYoUXbc1U83l2D6Eta3j2qmQpU6L4IVolua8+jYQL6ZNyAgY0wdkIMa09EJCBsTWtFnYmjYzW1OvWghh3TZy2f5B2+78kHaA/BHDJoghmqw5p70NBIxpC7IeCxw9IOVg4Kj0QgIGxNW0WbiaNjNXE1c1rJuqqdDTbflPSU5Pjr7aqp01BSCGoew0DNFszXn1bSBkTJuQ9e1I9ICU1yNR6YWEDIivabPwNe0UfE1FIZ4cslVF5b8Vnb4OPzkSsYhhIAIY4jmbM8rbRLwIGzAF+8JLL4t84RVeSLCAuJs2C3fTlnme+POjp7VnxyIAAhOAKNmbXGLvho3GGno3TC8l8m5YeCFBAeJw2iwcTlviOeOn9ePz2nFdBCioBBTK08a5eApho7F6CmF6KZ5CWHghQQFiadosLE1b4vnjh1jINEIjgFCeP84DELwGYwQDL60MIPAKLiQIQNxLm4V7aTNzL42qbRi6bli4vqXyp1IdPTsSdTqgoRNYEM29nFffBmLEtAmZjwoMH5BzVGBYehEhAykQ+dJmIV/azORLXMWaZllIQfUtzB8z6l+en4nCDINghmgC5rz6NhAzpk3IiBnTB2RgxrT0YmIGxMT0kGQlaJBUqYLUIFXBVj7xdI2tw/3PRWCGSTBDNBVzVnkbiBjTBkwTAs97QFoQPK/0YiIGRMb0cIQBMVIEzEQ20kwV5zAxOaatJyRSjWERvBAfMDOmug2Ei6j5WFlVYXoppKqw8GJiBcTC9BCEASvYzy+n3GOsIcPkH6LCbz8R4WsMm2CF8IPM46rbWKxgD2UTpZeHFQUNZ4MUiIDpIQgDVjBQMPkF0T3xu3buiGAqOw0zB5Ll8WBcabnjOVDINOTlhcMNGoM5Gm6QPo/xTfXaWRkQNxCgmGMcYkx6I59hjDNwJrktKRzWzkQMcEQGeA6kyA0a4H5LsK4LeIllDW2/9GKOa4jc6I12hnEdpzfqSPHH4lHzy7mXlYauVU1DNaZ7M5/3u+PRk97L7VdDMha8izQIQMuKD39SZDXofvmN/P3BiAx8TCw7Vn69QRvJ6Yy7b9zWK9clN1Rzp6GKXmCMq3Y95gA6jWWzHD+8DrISP3yIWHmYuP/QAnDoQUidvBz+oNwZyJgMrtuDG6rE0ZNnV9fbF87tI/r31fBRcBVdXHf79M/I7Tx6feXdIn/ILfJJb5E/A9Ibtm5dx/stSOdfjgf9vhu/7//gfT/aIhcjL8Pg66voR5oxGXH0njfw6Gfw2zQzckELI3+8y2YgeNOXvBlkNU0f/uJfBNk3/fybMzk3ozyBXGazifIJM5rLKZbVQkaxbObvTW/5GqNF+N9ehT9NU8eUGqk0VGikzrkSogJ2t+N9IYMtOeheu/0RHZZ05Gw9PTp5QTtd+KOHo+2zwddPaHePLu6bCYKotJ5hYjBBcTItVpTqF0et84N5C2Rhu6ooBCb1OQvUmVyO72iDaGGBDQrKFGaCiO+JEWSCLGKCRK9Zx3XL1wR9cXL0vFm/ixHCyjIjFHWRnG2QJ4VEG1Tbf9p89PJlz8Mu+pdAl9fh6XXQ8/2/FMu8LxT7O5PrIMW1n+A6uH8dgzp6FSb2frhyvPzpH8+CheW+DrN7HeT3OnzUv+895T/T835uhk82A5GbkczNUOhmJHUzzL4ZZN8Ms28GEjVDkZrTnKOsY3lPM4+eDB/NAc79vr0M0PE9BnSIBu3BPAOgx4nQmqJViaYWpxTI0HVkV03EEdBpYSGg+2UKA3RMAB1DgG4TQBf9YiGu23UBdI0uISUDethFcgZ0T4oS0EtALxygQ5R2D+YZAD1Oajcw/jJhlUjTDE3HVURJF3xWibzCZC0TqQTSVQDSNWWnoYkOvxHX7XosE9G2WYd1Il+OcqGoXCgqF4rW3gwhaJeEZ5wYzFB8nwTWdXheYWPVqKpYjwVsyb5QRAqTNK/QiBHSICOEiBESHdIlrtt1mVdgGvZf+rzCk6KcV5TziqLNKxC4hQUxbWFB8S0sGCkwoFs6wlVNs+z5WUUWQJ++fRYN6DoBdB0CdEwAXXQInrhu1wbQl75+Fgbokt8+l4BeArocQAd3GCGmHUYovsMImxgGdA1rtl5VFcQRz0lZkvDcIHhuQHiuEjwXHT0pptq1gXMTrwOcm7iE8xLOCwjn4CYwxLQJDAGbwEBEx9io6qqFdZMfpM9SxIWhOvAGlyC8KjxURUyj64LkK6nlosBcwG6wEs9LPF9PPAc36iGmjXoovlGv5Y7H3f7VqOpMxoO2+4YADKnjHEdndkcvxcYrd7gEuxPyFArXBK1F0234YXQMeud0mADKocqXwPJcRovgPM0jHT7PZRzgdBwz51LMbs9ZMphFDSZwRxxi2hGH4jvizrYQUqr7J/WnKBxBB+6oM+ze+N19MOrSLloZjQfdzqvu4NodD7udSmfgXl52O123P65cDoaVkdsjTeheVG6Gg4tJZ0wSXN+QAdIfV4nyYhnGIvsgTVexOiXRef2b6sz/wuJy7fUGndejql+JRp/6W15Vqqha228ctGR4XZpJps8ygv1E+sxhSPuKThzLXgMsGchB/1ocwCi2Z89rsemmvannpd7J1wpkSna1zlrnJ439REerdeN2upfdGT/LvXQmvfETVP81qufwcqX/NeMLoIz7+faOTmgQoeUWHkmx8OB2PsS0nQ/p6wFKiq5rpp4bKBE4OTw5koNLFsEl8UGFYiq9r7gUNFoJTfcYmsBtXohpmxcy1gKaTGQqimXhnKDp8/r5yXFdDjLZBJnEhzCKafSeIlPQZiUw3WNgArcrIabtSshcC2DCtqpZlmrk5jMd1A+/OqjLQCZd2WnoognzMyq9p8gUNloJTfcYmsCNN4hp4w2y1gKakK2puidMLtD07HmtUds/OZICTYhAk4STMacqvafQFDZaCU33F5owuBkDMW3GQPZaQBNWdWsmKAhfaGo9f3bUfCEFmDABJuEncsYVek+ByW+yEpbuMSyBWwow05YCrKwFLBmqahg2QvnB0qEkWFIJLAk/EzSu0PsLS4clLN1rWAKJ8ZiJGI/RWsAStrGCtLyWmI4a1PJu1aTgkkZwSfjRpDGN3lNYCtusBKZ7DEwgxRszUbwxXgtgUiwN2Ro9gCNPZNqTgkw6QSbRp6POqPR+Q9NeCU33GJpAtjJmYitjdT2gyVBNy7bycproCZi1/XMpyGQQZBK9sWVGo/cUmYI2K4HpHgMTyPzGTMxvvB7Mb6TRhVrLzM9nOpQ2mzMJMkkgf09Vek+RKWy0EpruMTSB/G/MxP/G68H/VlSkmt65cHlCk5zpnEWgSQL/e6rS+w1N5XTuPkMTyP/GTPxvvB78bzKQTAUbeU3njrf2T5qnUoDJJsAkgf49Veg9BSa/yUpYusewBLK/MRP7G68B+9uqGrah2PUtJTcekzRYMpSdhiGa+z2j0HsKS60Slu47LIHMb8zE/MazzG+M9So+PN9q1hrH1ebJUb39VaN+dACB1Fddt0eQxx1WJv3uuHLtjEaVwWVlPBg7vcqlS1CJXEWANKqMXznjijN0K/3BuNLrjihuOaNKg6hyPILxCleTt8954/UJUqJ/wRBOh2C0vgdEceEvUd19WJtqoHp6WD+WtBXY0Ai0wZyD8XCSjGz+zbuFhapK2mYX74DLDn2Idc1FeAvaKgZyEaYxnTCcDG2z4i3BuEC29BinlPg2j28qSB/HTPRxbK8xvilrhm5ICrrpBN1g3kJe6Kbce2xDJbZtCLaBHHSViYOurrPvtj7Ytv/Vvr5Vk4NtNsE2eK2sxLZFbAtaqsS2DcE2kMiuMhHZ1dJvY8Q2QxK2mWinYcI7mktsA7HNKLFtc7AN5MKrTFx4TSmxjRnbsBRswwTb4E3RJbYlYRsusW1DsA0k06tMZHoNldjGjG2qFGxTCbbBO6tLbEvCNrXEtg3BNpCPrzLx8TVcYhsDttXOmrKmpDqBtvJVAiu0+Q1VItuGIBtI51eZ6PyaWiIbK7LJmZAaBNngLZQlsiUgWzkf3RRkA3cDqEy7ATStRDZGZNuT47NZBNngfU4lssHItlf6bJuCbOCGApVpQ4GmrzGyoWrynkwp2CbHa7MJtomlf3iKv9/oVvptm4Ju4L4ElWlfgmasMbqtj9/ms0GlgJtBpqRGOSVNx9stsW1DsE0D9ySoTHsSNLPENmZsk/KO1DAJtsFxgUpsS8K28h3ppmAbuCdBY9qToK3zngRUTT5aSM6uBCngZhFwE7vi5in+3sKb31Qlum0IuoG7EjSmXQnaOu9KwFVtndDNkINuprLTMOE4IPltltfuN7oZJbptDLqB+xI0pn0J+jrvS1CryTGLpPBApICbRsBNbCQQT+/3Fty8liqxbUOwDdyXoDHtS9DLfQnM70qlIJtJkK1ccUv1orTEtQ3BNXBPgsa0J0GP70lQVeOgUW9Vm7VW6+lZbT+Es3mUYcCO1njoOtejapjlyWTsQUWQsw8R1Re18/pZnkBx0HVHT3vO6NUv1/BOQ/gxtfwQYs8h2nhC1be77X+Pg0ag7UTUCFphGVxETb4IFhE4BGARtBojWASpF8AikikZJZr00UbtKBEn9p1ehzb5DFDEECAoOxkUlIyg0Do/q9eaq1BBkYIKIJ9fY+Lz66pMVDjEgiBB3WkIPyJ2MyHhEDPjAU0qBQxowcVEApD/rjHx33VNJhKciEICbach/FDWzUSCE3YkOJGFBCeFRQKQL64x8cV1XSYSHItCAnoKaokEPJDgmB0JjmUhwXFhkQDkVmtM3GrdkIkENVELBpSfXCIBDySosa8W1GQtFdSKuk6gg0xkjYmJrJsykWD/RBAS0HcLJRLwQALaZIxIQJNKQQJacDGRAOTt6ky8Xd2SiwSipgfWTkP4oZqbCgXs84N9aUsF+4VdK9BBnqvOxHPVbZlo0KyfH9aO64IQwd5pCD/NcjMRIWo3VhpCmF4KMkSlFxMdQJ6ozsQTNRSZ6CAUHJCy00Awm7yEh5TwkBIdpIJDsbEB5FnqTDxLA8nEhtOzk1OB4IAIOMAnYJTgkBIcopZjRIcovRR4iEovJj6AfEWdia9oSOUrHm/tPT8XCBCYAERJWuTzNjJqOtZ3ktEDct5MRsUXEyNA9qLOxF40pLIXietXF4cQKkGIksPIa35RTze/qMucX9SLiw0gn1Fn4jMaUvmM1O8TCA4aAYeS1shtfpEGHaL00uYXBcYHkOWoM7EcDaksR0SdPoEAoROAKNmOXABi2nSMCDF9QApETIsvJkaA/Eedif9oSOU/toRxHZBB4KGkQHKBh1YKtkNLGtuhVVi2gwGyIHUmFqQhlQV5LA4PTIIHJRGSz3JkCjw4loYHx8XFA5ALaTBxIQ12LqRdNbCuq4qi1bcUK4fNEvuNg5YoeLAIPIgmR84rcBOxImhE1h0Ufmo5myj8souJGCBf0mDiSxrsfEmzalq2gpCWF2IcHdQPvzoQtgRhE9AQzZ+c1+FGgkbUjqy4ET0gBzqi4ouJHiCf0mDiU5rsfEqrammqYhg6qm+hHCYjn9fPT47rojwOrOw0sGh25bwKNxE8omZkxI4ovRToiEovJnKAbEuDiW1psrMt1aqtY9tEGiY208zD79g/OTw5EgYdiECHaO7lvA43ETqm7cjsd4QPSPI7wuKLiR4gF9Ng4mKa7FxMVMW2oWPPaCo6f/R49rzWqO2fHIlCDxpMUjQxc16Hm4ge03ZkRI/pA1LQY1p8MdEDZGkaTCxNk52lqVcVzTAs2zKJy50DerSePztqvhCFHSrBDtGUzXkNbiJ2hK3I+pY1SC7nRWtQeDFRA+RvGkz8TVMqf5M026E4oNAIUJT0TV7YcJgOGw5lYsNhcbEB5G4aTNxNk527aVWRrquaYmjEHqo5bAL58pxcnItCCp0ghWge57wKNxE2omZk3RMSppezKSQsvZjIATI6DSZGp8nO6MRVA6m2ZSErn7nIUYN6hvTQKTHQYRDoEM3xnNfhJkLHtB0ZsWP6gBTwmBZfSPQwQf6nwcT/NNn5n0ZVMTXTVrGez1uUoBX3RKGHSdBDNCN0XocbjB57adFjTy567BUVPUC2qMnEFjWlRs4kDXco0t2wCGCUATR5YcRhWg/jUK6HcVhkDwPkh5pM/FBTajzNoOGEORU2wYgypCZPjEjlRxzK9SMOi+xHgCxQk4kFarGzQHEVq0jVVVPNh41xvLV/0jwVdYifstNQRZNA5zW4idgRtiJzvCw/uaRoWX7hxUQNkAFqMjFALXYGKKYcAk2xbTrvNnJ4uSoUNRBBDdH8z3kNbiJqtNKhRksmarQKjRog89NkYn5aUqNwiuKIq5hgRBl+kw8ssCOCLDAoKg6AHE6TicNpSY20uS8KB+g54WWQTT6n/rCf+SPrxJ+i4gDIyjSZWJmWVFZmrXUoCgk0ggQlJZPPRjHaaqx7xGhaOdvDaMnFxAOQiWkyMTEtqVE0W7XjA1GAoBNAKCNo8pkieM3GOkvwEsuZKHhFFxMTQI6lycSxtNg5lqhqmYqiaxbKLyrWVuNYFD1bNQhIiOZYzutwExFj2o4pYmP5D0gLj+UXX0j0sECOpcnEsbTYOZZm1TSRqqo26fh2DqsOZ3vHIsHDJOAhmmI5p8JNxI5pM7KuR0QPyFmWiIovJnaADEuLiWFpyWVYPjtsisQLi+BFybDkw56Kmo6VPRU9IIc9FRVfTIwAGZYWE8PSksqwbD2jzSaMha3aBCNKhiWfVYuo6VhXLqIH5KxeRMUXEyNAhqXFxLC02RmW+WGEKBa2puw0NNG0ys3GCHYW9vQBmRhRVBa2BfIpLSY+pS31/PLW/tZp7az2VBRGIIIR5QHmfDAiajpWjIgekIMRUfHFxAiQPWkxsSftFOzJKkaKadsWyuE1SFMwWmCCFsLplHEFbiJuNNPiRlMubjQLjhsg29JiYlva7GxLtWogXTe8t38I8YeOxtbp2VNh6xWaSpBDNAFzXoWbCB5RMzJiR5ReCnREpRcTOUB+psXEz7RT8DOriqLoWFU1xQtskw9yCFvF0AhyCCdszqlwc5GDfUUjSi8ROQq7ngEyOS0mJqfNzuRUqzYysalgK5/YVvtf7eviXA6dAIdoYue8BjcROMJWZGVdBMnlcC6CwouJGiDX02LietrsXE+zqiPVVG3FzmdXudeGwtwNg6CGaKbnvAY3FjXYvY0wuTzUKKqvYYMcT4uJ42mzczytqmJibCAb5RO/m7ShIc7XMAlqiKZ4zmtwQ1HDSOdrGDJ9DaOwvoYNsjttJnannYLdSSbmhqpg27RyYYbTJhTmalgENITzPGcVuLGYkcrTMGR6GkZxPQ2Q7WkzsT3tFGzPKtKIc62qVg6B8vYapAmPTkQFtNFsghnCeZ9xBW4iYkwbkREzpg9IQY1p8cXEDZABarMwQLGSggFaVQwNkSdQHsBBWtA8PXouCjh0ZaehCyeDzmhwE5Fj2ors3kbwgCx/Iyi+mMgB8kJtFl4oVlLwQunrQ6TZhq3YSg5rG7WzprClDR0R4BDOEJ1T4CZCR9CIrPve/dRyNr37ZRcTMUCWqM3CEsWK1BibtNVELWXomIBEGWeTGy6wr14EqaXhQmHXLkAWqM3CAsUKOwvUrlqGpdkqNvN5t3p6WD+uHZ+Lir6nqwQnRNNA53W4iaAxbUdG3Jg+IAU6psUXEz1AJqjNwgTFCjsT1CSj3zQ108wnCNfpV2f147qwFQyNYIdoIuicBjcSOsJWZEWOML0c4AhLLyZugDxQm4UHipUUET2rCkKWQpfucnjJetA4FXlOiK4T3BAe4HNGg5sIG9NWZMSN6QNSgGNafDGRA+SC2ixcUKywc0Hpwh1SdUMxFIRz2HpyfFA7FuZwGAQ4RFNB5xS4icgRNiLrvpMguZxtJ0HhRcQMrIBMUJuFCYoVdiYo6fK6ZSNDy2F9g7SfyCmKSRBDNA00rr4NhYtU85MovSzAKO78BCsQC9TDEQbESMcCRYqODdXScqBmIKxtHddOhS2KWgQ1ZPBAYyrcROCYNiMjckwfkAId0+KLiR0QG9RDFAbsSMUGJX3eUDScAzGDNt/5Ie0DYpDDJsghgQ06VeAm4sa0EVnPTY4ekHNyclR8MXEDYoN6aLIaNxA7G1SrWpZtYAvnc+D66cnRV1u1s6Yg5DCUnYYhmg46p8JNxI5pM7K+TYkekPM6JSq+mNgB8UE9RGHAjjR8UIxU27ANNQ/kOKwfnxyJWuIwEAEO8XTQmP42EjbCNkzB3vDSSyNveKUXEzMgRqiHJAyYIffU9edHT2vPjkUhBSZIUXJC+YQWDluONbJwmF5OYOGw9GLiA8QM9VCDAR/YmaE54MNp/fi8dlwXhQ8qwQfRXNANxYeo5Vj9hzC9HP8hLL2Y+ABxPz3UYMAHqae0H2JhswyNYEN5SjsXbPBajREXvLRSMMEruZh4AHE6PZRgwAN2Tieq2lhRTYSM+hbKIbbn0bMjkYckGjpBCNGsznkdbiJcTNuR+cTE8AFJJyaGxRcTPSBep4cpDOiR5jx3pCq2rdo4n60k9S/Pz0Sih0HQQ/x57rM63ET0mLYjI3pMH5CCHtPiC4keCGJ4epjCgB7sDE+9inQN24qVX1xxY+tw/3NR6GES9BBN85zX4Saix7Qd08Tu8x6QF73PK76Y6AGyPRET2xOlY3vSPRGagmw9B474MW1CYfF0DIuAhwy2Z1yFmwgeUTOysrbC9HJIW2HpxUQOkOuJmLieiJ3rqVcVA2HD0PMJnuG3oagYO4ZNgEM02XNOg5uLG+wRd6L0EnGjoFF3MAK5noiJ64lTRP7Mi6WFBGGFqew0TOHRPjcTH6KWS8XNQlK5Waio+ADyORETnxNLPffdbzcsCh8QwYfy2HeO+IBT4gOWig+4qPgAcjcRE3cTS+Vu+u2misIHTPCh5G5yxAc1JT6oUvFBLSo+gNxNxMTdxFK5m/5Bl8LmFyrBh5K7yfE4Vfb5RZRe4oGqhZ1fgNxNxMTdxFK5m/7hdMLwQSP4UPI3OR6BmAofDKn4YBQYH0AuJ2LicuIU8Tnzwgdh6w86wQfhMTk3GR/Y1x+i9BLxobDrDyBbEzGxNXGKKJx54YOw9QeD4IPw0JubjA/s6w9Reon4UNT1BwzyMRETHxOniLiZ05FkwqYXJoEH4XE2NxMewoZLcw6ZrMlFWHgxsQFkW2ImtiVOwbbMCRuETS0sgg3C+ZUbjA3sM4swuTxsKOq8AoN8SszEp8QpYmfmdEqhML/BJtggPF7m5mLDXjq/YU+m37BXWL8B5ExiJs6kmoIzWUXI1hUdGTlsD/UaUJQHYSk7DUs4eTKuvo3Fi3S+xJ5MX2KvsL4EyKHETBxKlYVDyQ0V9honft8WAwuIwEIOnMnjwbjScsdzyJBp3Esb5FGLMI7yKH0uw5xqtrNiqEcSFHOsg3xIzMSHVFn4kPzePxzWzkQNdEwGeg7kx00a6H5zsL5R8BJLG+J+8cUc3yCfETPxGdUZPiM2WrWnSzZoa6pmaYZu3O28UD93Wb7/0+GPTsf5jfuVO7NjulsTz99rj3Vz/AOhSr8/J6wAuY2YiduoasxYkQ8+5LqCGOJDThOAe7J6yB0TeCweCsKEwq4dgnxGzMRnVHW5mJDvG8cQE6SsFW4sJnB52SgGE4r7rhHkMGImDqNqSMYEEX5Cwd8ycscEHuQkQZhQVD9BBXmLmIm3qJryMEEAqzkEhWLTkniCAkdCc/6wUGw+swpyFlUmzqJqycYFEROIglOZ+eMCl41QonChqHMIFeQrqkx8RdWWjQtCJhHF3gHFHxe4bKAWhQuFnUeAXEWViauoKVJxIe/oKyEuFHvnNGdc4BV4RQguFDjuigpyElUmTqKG5OGCgKhtIS4UO+IKT1zgGLAtf1wodrw2FeQvqkz8RQ3LxgUh6wvFjtTGHxe4BHoVhQuFXV8AeY8qE+9RY+c95oQLQuYRxY7wyh8XuASIF4ULhZ1HgBxHlYnjqM1wHJHxrNaqkqo2289PT2dxwcBVS1VU1ZzuhHze745J45Bx431JBRh+UQFghCVWDyxjCykBbpyfnNM+IWJ7xAneeSEaN+IK5QUgadDCa4ElaDHtBoto4bdTDC4i+PDB4knQdvTrMtQIki1iRiBcjpgRFD2DGJPBdXtwQ1VJnn/09NHnj852t+M/ZsCUg+612x/RVjqvN0/rZ7Xz52d1Wn74szec2meDr5/QoOzRxX0DI5BcqTKRKzWdFYxsXDU0zdBtPWcwsmWAkbrzQvTkJq7Q+whGdglGJRgtghHI6lSZWJ0aFJkSRiOsoqpJLLlmc0Gj2S2j8uFI23kheg02rlEZcLRyW6lUPBIQLKIEpFwASQMppSoTpVQzF72jL06Onh41v5yFI6QrVQsjWzXm4KgzuRxvvxpmd5GCYqtBx84NhbyxIAJv4irju5hDVPW8Wb/Tcs4qnyhq/JWrOT60rFrCCR6S4f8ERSfCTW3/afPRy5e97Qvn1vv7avjI6830OujW/t/rbt//MnI75Mt1kOLaT3Ad3L/eHpBesnXrOv6vYWLvhyvHy5/+oalfh+W+DrN7HeT3OnzUv+895T/T835uhk82A5GbkczNUOhmJHUzzL4ZZN8Ms28GEjVDkZrTnKOsY3lPM4+eDB/NAbD9Hr719OjkBQzY6D4DNsj11Zi4vhoUnxRGbAVXkanzxOtZJ3LzADvS2NrA9UqfURheC/APS8AuAXs9ARskYWtMJGzNBjzso9b5wQJea3oVq9i01dw8bL/Y3AH7SYO2jtMZd9+4rVeuKytiTFyja4PoKx3wsG+UDniJ5yWe54PnIHleYyLP6wB5HsRzjFDVwKpJI/5ww/MZSoxMPFcJnot+nxTX6Nrg+Sp+jDA8z58RU+J5iefriefgpgeNadODDgViBgHd1gj+mhq2eAL63JKKRETXCKKLfiUXV+naIPrqNRdRkF6uuZSYXlhMBzesaEwbVvT4hhV/vG+dDrsdt3p61tivh7B+4I46w+6Nj6z0dmVwWRm/cisj75EqUWosRRTC1zLn8P+T7V4q7HfHk5vqjFiNPkV/T7hqODEXCv46AX/he2U9TfKFfQLMZFSAsE+1ngj68dZYgvxB91nE/bDR0gF/+NQC8vvjcisoLhn+D2rntUTob924ne5ldwb53Utn0vMwJfw6Yw1CgRLNwSfbBPUefbLd6dAPAnbeHwKM9M+193l7Qf4Q0COfr/3Er/1br+l3+n/T/7kZPN/0bzf9Z669W2GSKE1wt9n0P59/HlyHX7y/yzAWZcLYoCUgkNX1FSA730hTiPV6afskkJfupHjUPDmqP/J78SP6f9CVo0QxWEZSYBncL6Qx7RfS1RxhOV9MDibXQjHZIJh87+OaSAPkoMVSAnLw1PoAciBQCcglICcAMrhRS2PaqKVrefrJ9jxzmTMmh7NjoaBsElAWHoTOU+WG4HLYaimBOXxsfZA5lKiE5sJB87lzFQzTOC5Pf4X4fYqPufG3h/7w9DvO9vTp1flDdBTk5x9fzd5z4Ozr3xAt9J0eUMbcLbgiKyzLQt1iZSuzkmzPlZdGNlgJLLLF9BITBq0SLewE50kG2btxJ5VNO0bMklL08+zMk/3BaPzLe9rOHgopNF4fPiSw7w7pUArswMxvNEUst9lkczd2n/a6N574AfwFKed/3q1NxoOng+G1M37yTc+TZPrL8YCa0ViK3b0BrX9tSIDCW+ScufbyetG9IMY7KG36w25Q6C1RNNHCeXccu6JV7PavoutGnyCFn7XX/WOXu013SETsX+y73sgfDyeknLkfQyNw8vkU/bdn2pS17e/UJaeDFmz7BR/kk9onaOeTxicq3BX8Kq51T8AieoIqtSeABBMWlzxNT6gZOw1k3NtuoInoBrrUbgC9l2Z5K62uMgY1pN/rtjdEtL0pte2h91csb6+0VBCA0U5DVe5tP7BE9ANbaj+AFsxZlsv1NP2giXaea/e2FyAxvqFc5xBap2NZpTOW9AM/RFnoEVoJs4P70AOE+IRIrlMIRbFhiWFjrvYG7J0Gvr/eABLiCiK5viAUNoQlaIiVcnKoahQLtPs7PURCnEMk1ztEUNAGlpANdsruoBm0Oxj310VEQnxEJNdJRNCyIWJZN0TLFg6hDmGotENExy7evw6BhXiLWK63iMC1RKbFxGWridMITBvgNGIhTiOW6zQiaCkRsawlomWLibGOcEI7wotP7u/0EQtxH7Fc9xFBa4mIZTERLVtNhCyE5QODeX87hBAPEgvxII+6o3Fip6A37/TC0Xvaf+sYfvVf8vsLT+HXXdJiJ5eXI9d77T+9mBOZipFW7Du9K1smtgqKjTiLfacXO8vENkGxMWex7/QiYpnYCii2ylnsO62hLxNbA8XWOIt9pyXfZWJjUGyds9h3WqFcJjYCxTY4i32nZbVlYlug2CZnse+0HrRMbAMU2+Is9t0WLkJhESC3LQS47zjDDqXFUPeG+zd3ye82FVwqOQwovK3OHecuSyWHzTxvw3NHb3up5GJsD4JsJmI2mqDksEfI2/wgyGwiZrsJSg5jIm8LhCDLiZhNJyg57BfyNkIIMp6I2XqCksPmk7sdguwnYjagoOSwJbJ5z3wgC4qYTSgkOYbdccR90gZGLmU2oiokuhgjisEQfsxGVIMkh40od8nBKSezEQUlh40ob/OP4bNoM0kOG1He5h/DwQcySQ4bUd7mH4P7c5mNKCg5bER5m38MbmRjNqKg5LAR5W3+MXg8EbMRBSUXMwfF4FkmzEYUlBw2orzNvwoeesBsRCHJVdiI8jb/KmRDVWYbqkOSi7GhKmRDVWYbCkouZiKqQjZUZbahoORiJqLgee6rj3MPxTUgyWFLxL23QDZ09YHTSyWHLRH33gLZ0NVH4i6VHLZE3HsLZENXH9q5VHLYEvH2W8Aj/laf8LdUctgS8fZbwPPAVh8HtkxyDbZEvP0W8OCg1ecGLZUctkS8/RbwBI3VB2gslRy2RLz9FjCU/OpI8kslhy0Rb78FDJq8OmbyUsnh2Rz3ZQswPujq8KBLRU8worytKBgGb3UUvKWiw1YUcX/nDJnR1ZGilooOm1HE246CQVVWx1RZKjpsRxFvQ6pBhlTLZEi1hDd0vC2pBllSLZMl1RMWRnmbUh0ypVomU6onTOp421IdsqV6JluqJ6yM8jamOmRM9UzGVE+gEfG2pjpkTfVM1lSHrSnmbU11yJrqmaypDltTzNua6pA11TNZUz1hTsrbmuogqSiTNdUTuGfcWVyQNdUzWVMdtqaYtzXVIWuqZ7KmOmxNMW9rqkPWVM9kTQ3YmmLe1tSArKmeyZoasDXFvK2pAVlTI5M1NRLWSHlbUwOypkYma2okvGjkbU0NyJoamaypkfCmkbc1NSBramSypgZsTVXe1tSArKmRyZoasDVVeVtTA7KmRiZraiQs8fK2pgZI081kTQ3YmqrcedGQNTUyWVMDtqYqb2tqQNbUyGRNzQQOPW9rakLW1MhkTU3Ymqq8rakJWVMzkzU1YWuq8ramJmRNzUzW1Ex45cjbmpqQNTUzWVMzgfzK25qakDU1M1lTM4G4w9uampA1NTNZUxO2phpva2pC1tTMZE1N2JpqvK2pCVlTM5M1NRPemPK2pia48SWTNTVha6px32kEWVMzkzW1YGuqcd9tBFlTM5M1tWBrqvG2phZkTa1M1tSCranG25pakDW1MllTC7amGm9rakHW1MpkTS3Ymuq8rakFWVMrkzW1EvaS8LamFmRNrUzW1ErgwfK2phZkTa1M1tSCranO25pakDW1MllTC7amOm9rakHW1MpkTa0EAhJva2qBW0kzWVMbtqY6b2tqQ9bUymRNbdia6tz370LW1M5kTe2Efd68rakNWVM7kzW1YWuq87amNmRN7UzW1IatqcHbmtqQNbUzWVMbtqYGb2tqQ9bUzmRN7YStmbytqQ1ZUzuTNbUTtpXwtqY2ZE3tTNbUhq2pwdua2pA1tTNZUxu2pgZva2pD1tTOZE2RkkDo5b4RWQGjM2Syp0hJCOPBfS+yAodoyGRSkQLbVIN/XAwwTIOSyaoiBTarBm+zSgoCpc9kWJECW1aTt2UlBYHSM9tWE5RezD4ZUg4oPLN1hYUXs1WGlAMKz2xfYeHF7JYh5YDCM1tYWHgxG2ZIOaDwzDYWFl7MnhlSDig8s5UFhUdits0gMASSV6UswovZOYPgOEjsgZAsUHhB8YQSQiEx21hQ+ASc5442cDQk9nBIsPAJr/i4Cw9aWPaISLDwCcuS3IUHLSx7UCRY+ISpFHfhQQvLHhcJFh7Gef5oA1pY9tBIMNrAOM/do4eDI7FHR4KFh3Geu0MPx0diD5AECS8oVg+CIySxh0iCogyihMhx3G0UGCMJsQdJskHhE3ZKchceNLDscZJg4RN2d3AXHg43yGxgYeETGKnchQcNLHu0JFj4BBYNd+FBA8seMAkWPuHNH3fhQQPLHjMJFj5htZK78KCBZQ+bBAqfEE6Ou3cABk5C7JGTYOFhI8XdOwBjJyH24Emw8PBEirt3AIZPQuzxk2DhE/ZOcl/uA0MoIfYYSrD0CSaWu40Fwygh9jhKsPQJi5X8Q/qCRpY9lhIsfUJIAu5WFgynhNjjKcHSJ0Ql4G5mwZBKiD2mEgKDtCfEmuPf70E7yx5XKUH6hO2U3KUHDS17bCVY+oRYHPz7PWhp2eMrJUgvyL0EQywh9hhLsPQJka24u2hgmCXEHmcpQXoxcRYRGGoJscdaSug5YmItIjDcEmKPt5QgfcI6CHdHB4y5hNiDLiWInxCegztmgnGXEHvgpQTxE9xM/mcAwKH0M5rbpKBX3Oe1YPwlxB6AKUH8BEeTP2yCBpc9CFOC+IIWFcAwTIg9DlOC9IKW7cFITIg9FBMsfVIwJu6eJhiNCbGHY0oQPwH1+Z/gAZpc9pBMCFz/TgrKxF160OSyR2VKkF7Q6j0YlwmxB2ZKkF5M2HoEhmZC7LGZEqQXE7oegdGZEHt4pgTpxYSvR2CAJsQeoSlBejEh7BEYowmxB2lKkF5MGHsEhmlC7HGaEqQXNMUCIzUh9lBNsPQJwZq4T7HAYE2IPVpTgvSiplhgwCbEHrEpQfwEY8vd2oJBmxB71KYE8ROmWNzNLRi4CbFHbkoQP2GKxd3egsGbEHv0pgTxE6ZY3A0uGMAJsUdwShA/YTGf/3lxoMVlj+KUIH7Caj53kwsGckLskZwSxE9Yzeduc8FgTog9mlOC+AmxhrkbXTCgE2KP6ASLnxDTiXv4WAQGdULsUZ0SxE+Iksjd6oKBnRB7ZKcE8RNoyNytLhjcCbFHd0oQP2GOy93qggGeEHuEpwTxE+IPc7e6YJAnxB7lKUH8BJYad6sLBnpC7JGeEsRP2PDD3eqCwZ4Qe7SnBPETYhHzP6oVtLrsEZ8SxE+IR8zd6oJBnxB71KcE8RNeonO3umDgJ8Qe+QkWPyH2E/cwswgM/oTYoz8liJ8QTZG71QUDQCH2CFAJ4idEVORudcEgUIg9ClSC+AlRFblbXTAQFGKPBJUgfsLSMnerCwaDQuzRoBLET9h8xd3qggGhEHtEqATxE/g73K0uGBQKsUeFShA/YaMtd6sLBoZC7JGhEsRPiFvM/5R00OqyR4dKED8hdjF3qwsGiELsEaJg8RNiRHEPR4vAIFGIPUpUgvgJURe5W10wUBRijxSVIH5C5EXuVhcMFoXYo0UliJ8QfZG71QUDRiH2iFEJ4ifEM+ZudcGgUYg9alSC+AlvdLlbXTBwFGKPHJUgfsKmZ+5WFwwehdijRyWIn0Cb5W51wQBSiD2CVIL4CQEuuFtdMIgUYo8ilSB+Qoxj7lYXDCSF2CNJgeLjhFBS3MPWYjCUFGKPJZUgfkJ0Rt5WF4PBpDB7MKkE8RMiNPK2uhiMJoXZo0kliJ8QpZG31cVgOCnMHk4qQfyEuMe8rS4G40lh9nhSCeInxD7mbXUxGFEKs0eUShA/gUjF2+piMKYUZo8plSB+QrAR3lYXg1GlMHtUqQTxE4jLvK0uBuNKYfa4UgniJwSW4m11MRhZCrNHloLFTwg5wj28LQZjS2H22FIJ4ieEcORudcHoUpg9ulSC+AkxHLlbXTC+FGaPL5UgfkIQR+5W
