Workbook

Sheet ASWXL.Storage
A1: ASWXL Storage Version 40.0.0.10 | B1: C:\Program Files\AspenTech\Aspen Simulation Workbook V14.0
A2: UEsDBBQAAAAIAJuByVpVb1JLuDABADAKCgAYAEIAQXNwZW5UZWNoLkFTV1hMLldvcmtib29rTlU2AE5VQ1gYAEEAcwBwAGUAbgBUAGUAYwBoAC4AQQBTAFcAWABMAC4AVwBvAHIAawBiAG8AbwBrAAoABAAAAAAA7L0JnBvJdR5O7pJckntoV7dkyYLolWVbO0P0DYyHVDAYDAdaYGY0GC53LekPNTE9Q4gYYISD5Mhx4vvIHTt24iRO4vi+7/u+7/vI6SRO4px2EieOE+fSv15faAxeA9Xoqm6gp7m/fYMGqrteV/X33qvqr16dO3/u3LmPkn/wF/499RgRn1LoHRvtPaNxb7lQu/NyZbmwv99sv5B5yej2mp32DTm7DP8J2RcyxUGrP+gaN9rGoN/VWy9kdgZ3W83Gi8bJXue+0b6R1RsNRWpkc/kDMZvbP7gIFb3x9PXvdLr373Y6919Dfny8/qDxVL3XPBq09D6prfdcXW/0mw+MmvvVU/XjrnFgdI12w+g9VW+2m/2m3mp+xNh/pn6k9/pGd13v6zWj//rRw2X7Bl7n+brYafe7nVbL6D5d7+rtQ6Oqt/VDo/tU/bDbGRwXGqSK3mvq+qDfOSKVN/b0w9vH+3rfeGt93WgZfWNPv9sy7twz2uZhs324C1d5R31glio9ahitjUG7Yd4KFNsmt+7c75vrPf2BUWm27xv75Pa2yTXMeyUnvsX8qXR019jfH/vxbfWDTrdhbAxarV3joGv07m23dwftYufoGFTahyYDvTcMHXqnqh+/vt4HPddaevt+sdOCuzba/d6b63rvoXkHBVPDHb1tlNpwvH+B/DtH/iPS/Hfh8XPXTvfbS3q3CYWL0IDmBeDxUU4XG/7cs74ZduXomW8fe/BqZfh/WB5KPX+61I77NIxe7vzHni4JPW59hE9Q5vInTC4zfD6g9FtOF971PDJQ4GNOF7g1fIpMlcx/mbH7PNVdUPS7H6+dkKf0aKT5bhlto9tsLK83zS/07skHxfe9zy5Y63fJ8/dC5qjX6HRbzbsexJqApcDrXU3TlYaiCnlJNghqP/DC+4JqUW73JZGTEtt3P0R0YHvxDzC+3HnovCuPgwDoXLkI4hL0/ZUnQMLhZRBXiLj4x8T4TnpooPgTD/TWwKjXz12GS8OVyXNELnTlSbjMU3B4Eb6lxOelut7t6ieX6o3OoN2/MP7Mlp3z3vcBEyLmDT1te4iLF0JB/HTlbx2rfHimt/pn7Ka7eJHKTrwWitYPB839i/Ut/ch4iljrXqPbPIYfn6s/aPaaYPT6tb7e7Q+On6u3muQBa+91qqTNCZh7r64bD4iFrHQOa8SxVJpHzf4FYkMPScnOoWk+H/UtvD1plSzAbb2+fkdv9ouDbq/TBWNPjHKbFHlzfaM16N0bqmfXQq7+ZJ3oWIS2MLrP1CvEL9U6rQfGXvPIeHW9YNt7V8+n6+SK7tHlOrliUe8Zb7S9zfoAFFo/aetHzQYp2XtDfd86sHzWRtf48IDYyZPXjH5/m3jQ3jOmrB0bDVOdx8+fN58zx/xD8z9pw/AW0fn8+ctLk56CEjSKfZ9m21jm7/LT58+PPafQfZ4HhtyRWfiS2fUX/pBAxFszPPWP1fXH6ncfqzceq+8/Vjceqx88Vj98rH7vsXrzsfqHHqvfPzf8d/mJJx6z/33eV9x74VXvvbX2ZZ/ye1/85c/98aVLz5Lf37lzQiz8Sa/Zq7+n0zZ6dUURSFDR79QVTQBP+94BiS76J5eeMy93/o9Iw1x6NTyU5n3skK69BJHL82JDzelSTltShOzBkizK2lJ+X9GXDCWv6IIgHKhZ9cprzWb41HedO/clf3DnTypf8zufTy70OvvpNv9dec6B2iVabweG5Wqlo+9vkBCh033CNmOXISLQu0b32U29d6/Y2Td2up0HzX2jexm+gCf7ArFkvUsvgYHpEdvyOAHYk5ffgtj8snOt57Efx64PPff77829+5NBs6twR1feAOKNcF+g7hTfDPbsDU7ctmscdSC0sm/rystHrVrjnnGkP0k+rTcPDm519SPywD5jq2aXMw3Hm8DovJmIn/mix1ff/eiolXlg2/hrwnL2WoY0ZIdEt4c3rg36B0uCeu3dN5++uvqot9Iza8g0929cc7W6liHIOzT6YFJ6x3rDuHHtXr9/vHL9Oqn2mKBvudM9vA4le0ZfWH7U27+WIVW2eytHvX67R1ua+qqPhkUfPny4/FAyS4rZrHD95WrFaqOhBgTqOrnNbtu+t94SsQDdTq9z0F9qdI5WSLklq9TwnONu53j6OVDqWkbvE4N4d0DsTKd7tG4c6MR33rj2YUDPQdMgSpMI+YhYBZ+fSbtnMtDydrEMsVDGSONbyq2Ue/aDceNavzsw3O9v9wxierum2W7oLcP+2byudeWGGSE/2js5Nuxv7e/vdZoNI3PUbG83GsR637hGnowj/ZFzNGjfJTZx31FyeOKoqmRw4LhOUApaZcXztInes/0VGv7as8z16Z+wqsvrbjPsGvr+drt1cqp1CmQIU243uuZZzm99UvGNa+RqxN65JYM/49cpNITreSrsmc6Tc50ep8+y6tHnhEYR08B6VNjvDOyHJDIVTPcebyvYjjReJczgOl4VzFFjhH2xet3PmJi/4EbI/MnWm8Lq7flZveyZtnpzY4HMZy5eFUiQuEl6yejudh56NLnb6bQMnTTPvhMTHOitXrTGkajm6an50w8eYwib9H68XbjW6ZL+K3QhGmKGo9ma405zv39vzrrJNIK1/kkrZqTtNftzoQfAndQ5B5qU222jaz29MT63VYPUUWjvFw2Y78Ee3giVqfX1/gCLQlwAbb+4+CFJpdnrc4xAzDogDIkwpijea7b2I66TuMTtgwNyTkTo4f58FJzJijMdng5bIVbrXOy0BkftGA2z7ahi9lGH7U7X2J/HmIahtZnFUY2GD1HXv0bOjjiE4Wv+qp19o5XOVPppyHqmMvgTNzezBqfnLWNQwZ63tB/Sqn6yqT8wts22IRfZ68atX6XzcCSUj6OJjo/jVmEOZlXBNMWrwY4+MiMRgwbDt+hzMNsY89sGE5jFln507FZb1E27Yf+WsX+cq3DLxLKP1uZvc6l1sdPed9/unFYbfmzCR2M/MxevgEAh27NN0nUOnJ8TIU3s7pHgKRJkNYFFajdUzBPSeq85jA52us1OlzxeN64tiYKsyTlJlXPur8Nwc8MBiPm9G0zU+np7X+/u2+SE3gsZ+9Nmc3/fiPlOLe6j5eROP7XWbxnnx0BtsWc/PQvXFFaY7tMUzo9JbwpnFIc3hvMrz+aIec5kXfB9BuzfEnjP4oR7FhN6z9KEe5bOAtTL6/KEJpDPRhMoE5pAORtNoE5oAvUsNEFFv2u0zsKNwjoDvdmGuZ0EmnT37up4UOv+zjOujXm6xn4Fn8Bbs7U4CzBdb/aOW/oJHoLbP56ZAcmgc1TvWJoiE1jtZj/TOchUDb036BqZ7WHBpLdLUW/XS8D6qZf3EVuntzPmrxnr9VjiZzNMDkvdXGmGtAb8mHF/THxjrDfJQc+cSzsDdwtGoG5SbFHzYP+S+GYYhj9FvW8cdrr4zLkdAnnLJL5pzEnd+rafFzF/ntl3LGKDuM5jguc4Ew2xqffqpnfoGu3xtiC/Zry/Jr45yr2WoR+MN0S5l6nYPyS+DaxIorw/wWBY8UR5PblGgztd1nlvm/LC+K1g5duJpUfESbT1Fv+e5N1OUx7RJBDUHYZmuqoS1XBu+JHpqsopqs31qsqNVvPYXrJ3ainUPGiXrvlM13ymaz7TNZ/pms/gIVO66jNd9Yk/Iem6z3TdZ7ruM133eRbXfe7ph6JpBLEZhbO95tPKGOHR0508Jr9kXB51rHio7rd8dDQ7dU60JO2FM2GgIVlPDc7UiLh6VhvGr6CVf31cPzsv+3ytBDJhgy6ksmATe9ZDEzOogg5mYl/jBVsKOGucx9twDtI2kjb0UdBqwzlQMV1/yEdTe3E7vnzWzIoec1JTa+U7vlB2DvSbvgbZVNJa04sb97laezxP2kLibysRerx97JN3wHXKI1F3tG+mYrbK5M6rJgc81u7RD8fmsOJRA96FxezJ4TGMVo2IRrTptF46rZdO66XTemd6Wi9lC6EapmyhlC2U8nFSPk7Kx0n5OCkfx6NOhFFJSshJCTk+I4FIQtO4Y1DL7MU8H7fRacccu2wNju4a3XmIou509eM941E/ZgdQBifU7HSLnVYn5hS+8HRErAZf82Jh7gwZmUqzPQ8R5x2jeXgvZnibD3K5vW88SsrTbE2qnqGnOfVWqbea/HQkylvtdDsHzZYxuvIznbZNp23nf9rWJIDNpWZzPaFM9NvdG3tXOg+abXW2D0h79WKcpttrHhmmu3mgt2JmbhBN5oDimL5+SF8/pK8f0tcP6euHwOF0Sg7ztEis3J+UoDZiFVOCWkpQOwMEtVrDaOvdZied00jnNEaGv+XtNR2isrkcm6cTLjNoBrarSP6HS82lgnM9IzTfCcnmYFYonQRJJ0HSSZB0EoRpuK8/MIqd48l7rEaPoVjnZtCQ0eiRavpb4N7nzTXtGk0SEjX1VvMjxpypVtUb3c6acUCG2jWjX24fD/q9QqPffIDlpICyGatwhpTOWMUzTvkJNxZ56g/Pfe0O2lR3RMrN760UDogpmnonZqn5vpFTzxrUSP+kWaUn2Jx2oXbHGc/XT1UV4/NHcZfQabPcHjkvvqdx0n0Nn8Vgt+VcO3IvW+k09L69zdHoDcGvmeHPsZK+bP92WsWtzGnHZ0ZNbhsL3LSMZnIufUnibY1YJ6Ct1xPQ3DFTDtK3NfPztiba9yKcbY5xrHf1fqfbK7cPOhwNzq1uZ3BMaou369aNRvNIb0WqB7sOtMrf6zTd6/hcAW580G6SKu37NrNVvmgMU7LtdEk7dE/IV7ZpH1ZiatsyGuShyDw61vv3blxbvn79qNdv91as5JxNK7vB9ZFzDppGa985wSoNGLnu1dTSyU9Jz8Wh9YudNukZHbDFQzkrUgugntPnpM1ENu24x6cdSYT5cgW0JVopwRUyF4hOV8q1glNLusszZ2tsgUFje/wnz9aWw6rqcM45IcyrK4tmdXM4cjAFcG3AKFgtDgoFhr+37bSwbXd6CzDO+qqsnssILFZuFpXmwmaNoCvLpMk52i03KwBRzDManN0YOKkVuSkKjcFW2Sia13zm2KrNCYXjeSIC2d7TOSbihqP5jo9Jw9tvC1m3t2dVNBM1vausmSvrWfTKRFnvIlrmymIr+Oq4QxyOMrbYu010JSHXu3UtWt3HG0263/BOC+d6M7/jERpjHB07yqPkdn8x9+b4hDSLO71vnHSNA6wnkfpISaM7ucP53cuYfzJvyNLf74ZGRnD+NzQ6auR3C95Z9AB34XElpx51W/8x38UHN6Psrlm7wccqheiKWe2cZ+VHgJvB3Mjke6JwgHxvdBboeEKCyXc3FovwvZdTQUow+OAhQDgUzRhWzAym0eAeC/Xt+8EGPVGOH4Ldy/Tb4H4H+LiG+uE6PSIM91gFHl+yfqDGkc7ggYrQak24kRlN1kx3Edxeed6ceCZybNXdd0fsZ4KGe73N6trH1Z3FnQfRebj32ww6mw8YRRxC656jfsLZPt0RPNnjDT86ZRy27cNOQAd93ulugfa5n+UWQrospoFQlBGQ/apm7M0N0vwCt7dA2CsuavtuttI4eEfea1Pby2jdKkuHGoUrdeIaFKmzNXgElmY0DEB1Dx4MRGteRogVocPhaE3LCH8FMSsaFx7MVHtyiopk0Zka94wj/ealjzl37tzvfenrV/ebBweH3RXrj36UeXTUIpe2Zh9vXBt02/YZvaWjZqPb6XUO+kuNztEKKbdklbpmn2NdYto5TkVLD4itXXUbybrGdMbWzdURp5qx1W/un/K2Q45Et/NwGzrYZHjZxe/pveI9c3O3G9ea7Z7R7Rtw6fL6zezqdSJXYU72ZnnrpVJtr1ra2ltZ3uv09VaGDN/3B41+pqa3jN7qdbPUqrnF5E1Ny4qSlCXnW8er5vrim7dr69dfMfTu6nXreNXkeu0aemv1uvlxdYf06M29zvGyfnxs3sJyrfmRZvswo7f3M8VOr08+L5ceGY0BrJWoDY5gPnh5qm7mZVdrzaNByySE39w56XZaJ71mr/6eTtvo1RVFqDfb/U5d0YT6QadrP02r1z3nrFo74N0ENd6+pq1et49Xh3sy3jRXA61e93yzOtwD0fnV882qZ5/Rm7c6nf3V695vVt2NPT1NOvxu1eE8O1d2j1crzfZ9d+tP+8qj361u3/0QAZ7Z7mijeX63y55+EJwyTtcPSW/4FUdKkAdMGL0YfEG+FW+e7mD4SYSfpJvjjwP8KMGPMoE++aNYf1T4U9HvGi1cF+un1fVm77iln/jr7C2wWtTb9RKsMARoDA9WN/Ve3bT4XaMNP40cr5Z7LUM/MNFkfVq9PgJPWhiLCIwFChgLHhhvL2d2IOPq/rVRxJ6GKm+YXttZ9qrCAaBCNmKE8oHmsI188Lg9AYXDk8eht+0B3LUdD8ROYdLCFopJ2cSbDyaVUyj0dDiKvpHf5wh1EoI6kQJ1oo/zXDd6za6xn9nV+0amc5DZNfokSBhFo3gajqRdGiRuuf5O3rj0044DQPMR41PkA1C/FgvlPv0uGpMH9VMHgbFf0TlCtIwgWqJAtDQxHN4mj6QOzWk26yieBS0vktgtxoD4tHYc8KxEjGdPo3ILiU83G4OY+PQlYw2KTyvjGxWfLjhHcFYQOMsUcJYnwvl2v0keuKbRQ+CsiYqWj3N4e1o5DmjORT2+dduUG5hPtxoDMJ++ZKxgPq2ML5hPF5wjMKsImBUKMCvTpqqgGzNF/bgJx+OQlsWcqGqoh45ktgpRjwOo5YhB7WlVnrNWSOOxmbxCLhz3HBai0qSpLKT4HKFdQ9CuUqBd9aAdgdw6GYE0+nBkNj48OKfG16KsKbk8B7SjVfOY3RKjHj0Pm4zHIBprNh8MY/DxH0hjFx7HMA5JC8oWFiXrj/8QGasIGx9j5dhBUggLyRwCSY0CktpEB7yrP8xUddjrizwnWESdz+ezYowRNaYgB9iqUUfVbrty879YyzHwvthlY/W9mEK+nhcrPEd+N4+APEcB8txkv2vHGRMcr5AXZCmvcHC8eN08PK8Q9TzXsM04gBhvNxauF78yD9+L14SAEy84R97Xs9htiMw8BTLzXmQafWjF3rLR6LQ7R81Gr66buSVPYdHFoNnPsDfaodGdADr/yzKFmblJm3Xl2j3D6L+9IK6Uow53BS5gG285P6DZbT0BXuPXQqDlXiYYoMavjYBpvNAokAAc9WJn0O6bUPIcRgUmjPck0BCfhCwKp44+6Hd6OjsgeS7IEkJmRy4wSjzNEgIfnqswRIbnqhgmPD/PGxpQ+hAVf8hLINp5ZXe7vLVcenlnV3Rg4NkCAxo2c9whD2qm081YOegyD+D5yJBnNlM7NhoZ49Fx1+j1SOnljLnyW2/3X4DiG51uv6u3PQUyzXaGeIOjHrxK3mh1HvbAI5ALdsk37cy6cdBsG5nr7pnmz73lzC5sGL/UaDUb9zP9TsbimGbcNgIS7wuZ/j2jnRn0SJN19cMlEn8s7Xc7x1C+0Tk+gUrM0j1IyUqq2ffUaNdDOtlz67Y5yEvaspBX1VGrAJtt+5sE99YgEto2L9czuRiH7SVos2W72c20yE7jc/a62ko5apLjsOk4ETXs5vS1K1YzT7AqdtOPGRTLUFAaEfsitv0g2vZ18lB13dqH3wx/rFv3UKqVb20t1XZKRU8x67dVK8H/TbjB5kHTII1hfzNiouzK8aC3Xt4fiXvheKLtGupQJMPdw073xE9H93dPiC3EEWJjhC6BhtEleClde0uSkF3equ0VbpUwO7g1OLprdMFsEftGLvYCMWWN1gDSvhLz0t434NLmoKdr3O00W0YXtybScKhsAg54ZdYHC3Q38+SfDTfaAGSt1Wnc7y1bt2CZFOdGONuU3EoZf7EM6Tx8TYr140wWReIzarZa0NeMmC07wYo4rR3OjDhXGbMjdvX+ZmS3sL6xWwhmQqy05ObjZj1yzjcj1sXRiZ95WatsF1+cS8OC8coEGmKZII0Zlo1Sab3ua1w2DBKNmHYl0zbtDG47hPwp2yGcsh2SEN5yDDVdJl8uCdxtSH6ljFNHedkQaMb5syHeJ2R8fGN3RbDBjX1SNPbEYyDses+izcDIawINe02Qx2zGWqFWrtV3dzGLsWsctAaPMsDh62Q+YXhkQKv3m60W0HXh+BMzD+81G/fIGAyiFTL4OegaRuYhvMswR3B6q5VpwL4VUMI47pPiZBRFoNHcz+zcgx9uvKQfd7pLleaHB839pQ1y+h04u9A+qYHF8jFVwrKknLZWpSVBOWWxhKz7b9R0TX5hgNitYWtxtldCdqXssxiFm8WyWpOV0VrTSVvcrG5XiKmxPjO0Y8N+CBcNDa8TaTwklN4FTY0GQ0OVYjFtZlfV7dmEm9VCrXYV+vBqbW/9pe3KVbsv3QJxm0KM+ifQcP8EZdQUilGMy4TT1orpuEyMeFwmCMRG4S82udkohgYqkDUS4x2ZienILHLTgvEMBRqioaCOmRY2IzNp1HrAo2OZCnH2IZmIDclE/hPFgkiMB/6ClpvxkObReEwZkoli4AGZiE0TczEi3uGYyHV+eH7NBMZ9FGjIj4I2ZiYWeTCWXZaiGIqJ0Q/FJGKppEgtldmW8zIQm2i9ohmIcQt/0oEYKzOIsUMFGnqokBs1g1IkAzGR50BMinogJhMLhS/T4hZLiTHFUlK8AzEpHYhFbVpEjN4q0PBbhfyYaWEyEMtxGIdJ2DgMnjbetkMhtgPPwsDLduTm0XRMGYZJ2cDDMDglGhPiHYbB1c+ikcBouyINbVfMjhmJxR6GeUiEHMdhUvTjMJVYKnwtHL9xGEtaYdiB2ET7Fc1AjFv4kw7EWBlCjLEt0jC2RS9j28r2cbJUGxwt723v3d4rbtf2RlYwmFEPLL6DDxSmY9fokZ7tZZzltN4atgd9MCWeitivwbPtxyePGxaJhEASh0RUW51+pmb0/awLtBur4OdU4/paEU+jT1pMO+yHcMbEc6Exa3J7r1xZqt2uVgu7r0xkLxf2Cr4WBZq4obca0ON+IZFHiRH7Megc1Ts2aJ+/vq+fXH3++r0uEUfNNpEEGw3yp0P6dunE0OEH65uHhnGf/DG/u2+deN8887639H27RLVqFYG/w1/h6MRco+7VIoRJW28eGW1Y/HAT7nRpt7BnDhadL02k1nc7D6FvMPr1qUbGwro4ljaKaCJNqkyaXt61JKq1wsZybW+3Wr+9szNmx2hWD/e7hn7UW7YvZVss54rLL1WIO9jYXa6WXy6tgyErVJYLu9WlAv91jrDQkcNKxwitl922vlbLavMJBmvYseNDN7tnPCv9zT7yLO83e8uTtdbuNydV7ZhVs38fs2iOmv62rEpguVuGyk7bM69lsq/vG+yYGB6C3wfSpE1KhepcghrjPIs0nGdRmgtQr/EHtURAjb9zSkE9M6jXpoB6jTOo15IMaoyULNKQkkU5dlCXt9YLWzX+qJYJqjmk0zu7qHY6zhfWTgFuuHYqSC6wMYqtSEOxFZV5AHZpqxQBshWC7MWeQpg/ZFs9NwnaVgme2LZqSC64MZKrSENyFdXYwb1V2Nnc24RO5I1ulaCbQxa+s4vuYdf5wntYhBu+h1UkF+AYPVWkoaeKWuwA39ksbRW29jb5A1wjAOeQt+TsAnzYdb4AHxbhBvBhFckFOEa8FGmIl2JuLgC+XYkgPM8RfHPYnOJs49vsuYnwNktwRbdZQ2LBLWHUR5GG+ijm4wf3duWVpcJulT+68wTdHDaGO8PodrvOH95uEX74dqtILsAx2qJEQ1uUsvED/JXdSCbXpOxKWcJzYaT4ng3fTs/5w9spwQ/dTg3JBTdGxZNoqHiSEADcQUh4U1Be2XypWlsSFC/MecO7Kq7cXkD6ikn6hKtEhXKnb+hhPoGVx3Vazb6+L9lurT+43rp7taG3rh8eXb0Ff+8fXn0PiPv2wX3zqGqXrFpH7mHVKVat7jTMr6w/E9h0iC0ZsuOA07tU2oKpwJ0grLk5Nj0Yb06i4c1J0fLmareWdiO1NtLK7ZRX42tkoDsW08AkKnBAN5um2m06WoIcGM6N3VqkAJZXbqcUGl8A2z2SYjh2DGN8OImGDycF4cONBv+Fblc/mRnN6zl1SWC84th8oFKMjmDUaeeAe0XaZ3FDpFOBb9xevLpx9cWru7NG2Xul6k5pt7B3ezfQ0pTQEBd4bYgnYcw4iYYZJyHMOMtyw+pJVm7auaLtnu/AU8DYPW90P7LDba+thRzCD7sRcc6OK7Zds90jjmueYgDs0tzwb18/uR4Z47pJNFw3CeG6cYfrJuscjDZWpZXyAg6AY8fqpkgN1E0s/yIrlG5OSrO48BDF2GoSDVtNQthq3CG6zQmi8kp5AYe4sUN0mx6i2zwhup1oiGJ8M4mGbyYhfDPuEN3iBFFlpbyAyz1ih+gWPUS3eEJ0K8kQlTHWmETDGpMQ1hh3iBY4DUrVlfICrtmIHaIF+hFpgedwtJDksaiM8b5kGt6XjPC+uEO0uM0Honx2i008RKE7KCEKRblBFC6eXIhi7C2Zhr0lI+ytCCDKKdL13X01xehkjNKHukWuw9FiosejMsZ0kmmYTjLCdOIO02ppb7OwxTolvA1V301OU6hOgqrbJ5Rwdctzg6xbQ3Jhi1GcZBqKk4xQnLjDlidqJ2z1meJ2Em4DwpY7apMPWozTJNNwmmSE08QdtDu72zv8UOu/+WWK2kmodXuFErZueX4rkZwakgtcjKkk0zCV5DiYSltLa7f3+CHXf+fJFLkTX9643UL7Csc9gd+LHLeK5IIX4y3JNLwlOQ7eEomCStyg678VYwrdKaFyKVioXOIdKpeSDVqMySTTMJnkOJhMEALxQ63/9oQpaqeFykFg65bnGionHLgYv0mm4TfJcfCbBIh/+CHXf3PAFLmTkDvsFkroDk/ght1hFYkFr4Ixn2Qa5pMcB/Opxuud7YSt8lLcTsJtLcBb2xrXt7a1RL+1VTD+k0LDf1Li4D9tcQOqRoCaUqBmmIsKANQtrkDdSjZQMRaUQsOCUuJgQRWK5XXWCekcqOYIVFMm1AyEYqtPaDnFVml+tGLr+skFLMaHUmj4UEocfKhCZb20+co6r/FrnmA2pUTNgFm3W2hh657AD7luFckFL8aKUmhYUUocrKgXS3vb7BPAOjklsitlMaVFBceu2yuU0HXLc0OuW0NygYsxoxQaZpQSBzOqUClub7LfeMFBrkCQm1KjZvG6TrdQe13nBI5e16kiueDF2FEKDTtKiYMddet2oVwobrPOtOiAd0G3E48dvMNuoQTv8ARu4B1WkVzwYuwohYYdpcTBjqrdvlWp3uEE3QXdNDx26DqdQvvixy7O792PXUFyQYuxoxQadpQSBzuK9McmN9Au6J7g8wDazWCg3eQN2s1kgxZjRik0zCglDmZU6eU9crDHCbULut937Kh1e4WWieyU50dFdmpILHBVjBWl0LCilDhYUZUyRD9LBU7IXdC9vGNH7rBbKKE7PIEbdodVJBe8GFNKpWFKqXEwpeweWeME3gXdp3tewLsWFLxr/MG7lmTwYuwplYY9pcbBniI9ssnR8y7oJtzzAN7NoJ53k7/n3Uy658WYVCoNk0qNg0ll9wgvz7uge2zPC3gDed5N/p53M+meF2NSqTRMKjUOJtXWUnG7usNpw48F3T47dug6nUKd7cIqzjHXhVVBckGLsahUGhaVGgeLqsYTtAIBbcqhmuG1UDDQ1niDtpZ40GLsKZWGPaXGwZ7ixHmURILXlDY1A17pocoTpUkGKMaQUmkYUmocDKkiJ4DCvncpOWqGROb0acx5JjFPMkAxNpRKw4ZS42BDFWqbnCAqE4imVKgZ1g1Aj9AuGYCy/FYLwNWTC1SMAaXSMKDUOBhQtcLWOiekKgSpKf1phmjX7BLagNcszC/mNS+fWLBqGOtJpWE9qbHsglcsry+VtzjxFSWVADZlPc2WvMLqlgD5K6wTuKawsKpILngx1pNGw3rSYtkfb3dtiyN4NQLelPU0w9DV7RbaEax7Ar+BrFtFcsGLsZ40GtaTFgvr6dZmlSN4cwS8KetpBuKE2y20xAn3BH7ECbeK5IIXYz1pNKwnLQ7WU+0W9AcvyqKUJ+BNWU8zjHPdbqEd67on8BvvulUkF7wY60mjYT1pcbCe7B7hRFmUsytlOeU9zQxeesri8ATe4E0yZVHD2E8aDftJi4X9VFzaKexC33IBr0DAm/KfZgCv2y204HVP4Adet4rkghdjQWk0LCgtDhZUlS94RQLelAw1w07UQcFb5Q/e6hkAL8aQ0mgYUlocDKny0s7uBq8hrywR7KY8qeDYdXuFErpueW7IdWtILnAx5pRGw5zS4mBOWR3Ca7grE+Cm7KlZgUs/2nXLcwZuose6GJNKo2FSaXEwqYqvFBVuDlchuE25VDO83bU7hfbdrl2c35tdu4LEgjaHMao0GkaVFgejyuwPXs5WJaBN+VQzgpbe1zrF+YI2yZ42hzGpcjRMqlwsTKpXiio3T6sR0KY8qplAqwbztCpvT6sm29NiDKocDYMqFweDyuwPXp42R0Cb8qdmBG0gT6vy9rRqsj0txpzK0TCncnEwp9bKpEcq25zWw8t5AtuUORUctsNuoQTu8ARu0B1WkVzwYsypHA1zKhcHc4r0h7ZTuc0JvEp2paykzKmZfK7dLfRe1z6Bp9+1q0gueDHmVI6GOZWLZfe93SqvIa4iEOSmtKkZ1vlZfUK7yM8qzW+Fn3X95AIWY0vlaNhSuTjYUtAdnIa3ikgAm1KlZgMs/ejWLs0VsIke22IMqRwNQyoXB0NqZ7O0Vdja45SnRpEIZlOKVHDMDruFErbDE7ghd1hFcsGLsaRyNCypXBwsqZ1XdkvcdpVXZILdlCU1A3adXqGFrlOeH3KdGpILXIwllaNhSeXiYEmtl3c4ZkRWFILclCcVHLnDbqGE7vAEbtgdVpFY8OYxtlSOhi2Vi4MtVd5aL2zxcroqgW7KlpqBmmx3Ci0z2S7Oj5hsV5Bc0GJsqTwNWyofB1uK9AfHUFkjqE3pUjOhNlCo7JbniduEh8p5jDGVp2FM5eNgTAmivLRV2OE1QZUjyE05U8GRO+wWSugOT+CG3WEVyQUvxpzK0zCn8nEwp6A39jah37iAN0/AmzKnZtiuy+0W2g273BP4bdnlVpFc8GLMqTwNcyofB3NqZ7vyylJht8oHvGp2paymzKkZppfdbqGdX3ZP4DfB7FaRXPBizKk8DXMqHwdzCl7WbVc4jXdVgWA35U7N9lrX7JUAb3XN8lxf6po1JBe4GIMqT8Ogysey697tykbh1hYn4IoEuCmHaoZccU6v0KaKc8rzyxTn1JBc4GJMqjwNkyofC5OqtLVX2CpxAq5EgJsSqWbwuE6v0Hpcpzw/j+vUkFzgYiyqPA2LKh8Hi2pT5BUmywS0KYMqOGjNHqEErFmWG1jNqycXqBhrKk/DmsrHwZqq3Kpw3H5EVQhaU9bULNuPVIJuP1Lhv/1IJenbjwhZjDaVp6FN5eOgTZVe3tvliF6VoDclTgVH77BbKNE7PIEbeodVJBi9GH/KxPRU+JJScaWu2Sy+yAm/GsFvSqGaMXmN2S1B0teYJ/BNYGNWkWD8YjQqE9UU+I2DSLUFPcJrNb2aI/BNeVQzUDGcXqFlYjjl+RExnBoSjF2MRWUimgK7sfCozD7htLBezRPspjSqWbFLv7TeLc8Zu0leXi9kMRKViWgK7FLQqNgljduGb/hAVsuulLXIyFOhUBpfdji7/amTw9nlOeaGs2tIMDgxkpQJWQpwUtCkmI1lNwu7nJApEGRGRo1aSGRajU87WjUL8xupmpdPMCAx8pMJUwpAeulPipC1QFSpvjwW5t5uN/u9gPEuXNALTnLdZftJYYrLYqdHYCkShylmP7kMja83+s0HRu2eYcC+1dpKWToj806kyadB2OzdqRC2UDp1xz3rpDHsmmqEBa598RHkDjpH9c4xtE/v5q3Do+v7+slV+Huve9U+cg+Omm340zMaV+8fmj+RP+QnIuEn8qdD+nXpxNDN7+xy1mG/024b3t+tL8zPlSVy0DMvaH+8534JF27dNX8jf8j3RNrfDS9GDqAy8sc8rNqKVy3Nq/alhuWdb6wD+/JV6/rVkStX3WsiVxm9jHsd50KnruS51NiFPJc5/dvwJ6vFoArr0z3nq2FpT6O6Teo0qNucp2pwK1i97n0Wppn09eaR0e4BrAADSxuV7TvwZDlfmuatvtt5uIDmH6PQmU6Bwvx7SXRiNrv8UqW2t87I+sP1bOtvX5an8ScxmShgxj9HjP8ZmbUUs5OMv9u3nG2/qQVv218oblSv3r3bMm0G/CUmozE46JvH5gfnC7Ah5gewuY3BkV3iyCpwZP9+5DExcOQUNr841M3rwx/Tczj13ncud9++3n3nVOt38yzrnJb5ddU5s2qrXHV1rjpKV12tq87lq/blq87lq7ZGVUel6vDK7qU91x5e3D3TOXVWM/rSduV2tZQoQ4pRGk3zSmFIvaRGOSsvk+ZhFkbD9RxDal2WpyEViSEVMUOaJ4b0jEwhyzBR4W9Inb7lbEhNLVJDmhrSRTOkGOXUNK8UhtRLOlVF8WW2MxLmFSOckpCIMZUQYypnV8ryGVkZDW0+D3MSlh7ppEQ6KZFOSvB2AQLGWzYdA4UL8DKXRUVhGkvD9aKLpWVi/mXM/AvE/J+RxfUipKmNPZY2tUhj6TSWXjRDilLIBSoKueClkItClq0hHb7bi8CQKsSQKpghFYkhPSPJDsSJr/YiM6RRvNlLDWlqSFkbUpTLL1Bx+QUvl1/URLaGlFwvOkOqEkOqYoZUIob0jCSfIC0+D4YUtEgNaWpIF82QogsrBKqFFQKysIKlLR0lhPI0p8j7MWJapXR1crRGlBVHNLWjqR2N2o6ii1wEqkUugneRCzEO/Wb7sLesD4jtMh4Qq0DuccSewm1YHyxrCtbr0OhOMKg+1+RtQ4kJZW9BLbOHm8+b1mjWPmBGtj/VbD5m1GnlCYb01IXGzenwGsEs6qkL25bVawBPlRgl0A9xarag5zAy/KDrUASqdSiCdx3K7pIgZJeL26UNwQHNutFrdJvH1hPe6TXhEc30+p1m416zc2T0u81GptExDg6ajaZBTBV50DM9o0W60NjPHHc7+4NGnxQ4OiaYaPeXSeN5LuhAcjkrC7IiiZLigtN8vqHNrA80oc9aq9O431u2bqLchrjHvJVlYblQLK/XIop+ZI2MHzlw7Cdj19uEHFBsta0vfM02n4Bd+5Eax6zg3bkZOmm4VGYYHkkzBUS2Tv7x0G5tb7tcHI+Gan29P+jdrB0bjeZB0yDtYn9DwHCgD1r9m0LpXdDOzuHU+Mnr2+GWR44nWhDEW69VtiHXxGQ/LsTix9HlNwLV8htBmQ87lFUUWVO42aFKcXtzuxKZKcoRU8SB8T3VFLmtuKimyO6n1BotsDVCV4MIVKtBBHUurJEmaNlsLidyskYvlva2t0qRGaM8MUYcWNPTjNGwERfUGNndlNqiBbZF6IIKgWpBhaDNhS0S85Kcy8G0LqfIaL20+cp6KSJjpGRXygoH1vE0YzRsxQU1Rk4/pdZoga0RuipBoFqVIOTmwhoJeVlSTGW4WKNbtwvlQnG7EpU1Eog14kCCnWaNhq24oNbI6afUGi2uNRJRgrxARZAX8nNhjURJyamSymvWqHb7VqV6JypbJBJbxIFHOjUycttwQW2R1UupJVpgS4QyzEUqhrmYnQtLpEqSquYFgZ8l2ozOEknEEkX+EtzbhotriTZTS7TQlgilaItUFG1RmAtLJObFrCDzmi6qlMHZLhWiMkUyMUUc9jabPl1kN+KCWiKnm1JbtMC2CGU5i1QsZ1GcC1uUzclCXoas7zyN0VpUxkghxojD1m3TjNGwFRfbGq2l1miBrRHKFRapuMKiNB/WSJW0XD7HKzSC7cQKxb2ojJFKjBGHtR5TjZHbiAtqjOxuSm3RAtsilHctUvGuxfngXQsyTLrmNH6R0WaUwzSNGKMYqNfDVlxQY+T0U2qNFtgaoexrkYp9Lc4H+zorCZJm7lvE0xpFNk7LEWsUA/t62IqLbY3ScdoiWyOUfS1Ssa/F+WBfEyBpWVHlNU7bWipuV3eiskV5YotiIF8P23BBbZHVS6klWmBLhHKvRSrutTgH3OvcsppXs/nSUpYbvyhKS6RmV8pq1MzrkTZcUEtUSy3RolsilHctUvGuxVHetSgqy+Lm3lK1UN5arm5XSvVXyqXKOmaXXmkaLWJsjG5m0G72M0d6r5fpHGT6nb7eyhwYxBCRI9cG9TL9e3o/o3eNTLvTz7SaPTBVei9TJk3Z7+EmSlz2X6Jm4vWmkHX/2RAOZrTgftdJwznfuPduWbJhCyzvbJa2olthq8rEmuHEgH534G/MrB9nsmVmY8dhw7zP3KQs9p6ncdyi2d3jsWuuGaPaIdPfmo2qN8Gs2boFN2vZ1KSdNmkSSt4WqcjbYn6OTVp2zgyaEJVBU4hBw8kFvAwan7xDUZozITVnCTFnKANcomKAS/Mcoc2POSu+UlSWCpGZszwxZ/i8V2rOxs2Z3TmpOUuIOUNp5BIVjVxKozNKc6ZGZ840YaWs4QuFU3OGmjM1NWfJMWcoE12iYqLL2dScUZszMSpzJhJzhq81Ts2ZnzkTU3OWEHOGUtklKiq7LKTmjNqcSVGZM4mYM3zBcmrO/MyZlJqzhJgzlA0vUbHhZTE1ZxTmrLBbjXCsqRBrlr4JoLVmVt+kxiwhxgwl00tUZHpZSo0ZrTGLbKSpEmOGL1NMjZmPMUsHmkkxZigXX6Li4styaswojdlaZJFZjhgzfGFRasxwY7aWRmZJMWYonV+iovPLSmrMaI1ZZJFZnhizlKERyJilkVlSjBm6IkCiWhEgq6kxo6bPRmXNVDLOVNNxZjD6bGrOEmLOZHQ1gES1GkDWUnNGbc6ieqOpasSc4Ql1UnPmZ87SN5pJMWfoagCZajWAPM+rAYRl/41z4lkPEJU9yxF7Fu3MmdnWC2vRrN5JDVpCDBq6HkCmWg8gz/N6AHFZnieDpkZm0LTsSlnDs2nwW38uL7ZBU1ODlhiDhq4IkKlWBCjzvCJAWvZP9hMLUSMqeyYTexZtPg2zqRfWnpmdk5qzhJgzdEWATLUiQJnnFQHCnJmzqFLAahoxZ9HOnwkLb87WUnOWEHOGrgiQqVYEKN4VAZKkrpdLteVqoVbb2C0UHStmPuLQ/RSWotbvGvpRb9m51vagbxoG+5KWQVi+U9gr7TI2C+tNo7fR0nv33l4QV8octlbdIna4ZvT9TAI0UCgrsKaTG4ereLBvN6evPbCbeZIhcDtz3Ay4sLfNgN0tlGbALj1mBlyd/PFfhVPLhcq4BfAC2K7AF9Ogige25uE4PGt7u6VCdRpys7EgF6W/y1T0d0WKBbmbIj/YSitlDvuQJh+2myI1ZqEoP8DC1ROMVpTfLVPxuxU5FrRuc0SrvFLmsFVn8tG6TY/Wba5o3U42WlECs0xFYFaUWNC6xRGtsJllitbgaN2iR+sWV7RuJRutKENXpmLoKmosaC1wHMACvTVFa3C0FuhHrwWuQ9dCosetCkpAlakIqIoWC1qL2/zQCrPPKVqDoxX6hBKtUJQfWuHqCUYryq9UqPiVSi4mtHIMhXMrZQ7bBZ4FuNLHwkW+Q9disseuCkogVKgIhEo+FsRWS3ubha0SP9TmV8ocNtZLPmrdjqF9ueuU54det4oEIxhlzClUjDk1GwuCeQNYyK6UBQ470iUfwgERzB/AZwC/KEVMoaKIqUIs+N3Z3d7hC2CBABjPip8CeCKA3a6hRLBbnh+E3SoSjGGUF6VQ8aLUeHhRW0trt/f4glgkIE7JUbO8CXL7hvZ9kHsCx7dCbh0JxjHKklKoWFJqPCwpEiCVuKJYIihOuVKzxdKlYLF0iXssXUo4flHelELFm1Lj4U1BdMQXwDIBcEqfmjGWDoJgtzzfWDrpGEbZVAoVm0qNh00lQGjEF8QKAXHKqpoBxMO+oUTx8AR+MB7WkWAcozwrhYpnpcbDs6rxfBcsqATCKdVqBgjXArwNrvF9G1xL9ttgFWVbKVRsKzUettUWV8xqBLMp4WqWKawAmN3ii9mthGMW5VypVJwrNR7OVaFYXq9xRG2OoDblXc1CarY6hpbXbJXmSG22KkgwdlH2lUrFvlLjYV8VKuulzVfWeY518wS+KQFrFvi6fUOLYPcEjiB260gwjlEOlkrFwdLi4WC9WNrb3ipx9MJidqUspiSsGWDsdg0lit3y/EDsVpFgDKM8LJWKh6XFw8MqVIrbm9sVniAWCIhTItZMvtjpG2pf7JzA0xc7dSQYxygXS6XiYmnxcLFu3S6UC8XtCkccQ56qlIs1A46HfUOJ4+EJ/HA8rCPBOEa5WCoVF0uLh4tVu32rUr3DEcUSQXHKxZrlFZLdM7RvkeziHF8k2TUkGL8oF0ul4mJp8XCxSKdscsWvTPCbUrFmw+9mMPxucsfvZsLxi/KwVCoelhYPD6v08h452OMIYIUAOKVhzUKGdrqGlg3tlOdIh3aqSDCGUQ6WSsXB0uLhYFXKEBjBDgjcQKwSEKdErBlAPOwbShQPT+AH42EdycWxhvKyVCpelhYPL8vuljWOONYIjlNy1uw4XguK47UIcLyWaByjXC2NiqulxcPVIt2yydkf5wiOU7rWbDjeDOqPNyPwx5uJ98cob0uj4m1p8fC27G7h6Y/zBMcpb2t2HAfyx5sR+OPNxPtjlLelUfG2cvHwtraWitvVHY47o2RXylJK25opa4fVM9Q5O6ziPDN2WDUkGL8oZ0uj4mzl4uFs1XjjVyD4TRlbs7xjCobfGnf81pKPX5SrpVFxtXLxcLU4ki0lkUA3JWnNAl161HIFbKKxivKxNCo+Vi4ePlaRI1ZhB8GUijVLbnf6zO5c87onGqso90qj4l7l4uFeFWqbHNEqE7SmxKtZljFAt9CuYICyHBcvwOUTjFmUb6VR8a1y8fCtaoWtdY6gVQhoU7LVLOGw2S+0EbFZmGNQbF4/wbhFOVYaFccqF9N+gsXy+lJ5iyNRUlIJdlOO1YwpOKy+CZCFwzqBbyIOq47k4jiHcqw0Ko5VLqadBnfXtjjjWCM4TjlWswxz3b6hHe26J3Ac9Lp1JBjHKMcqR8WxysXEsbq1WeWM4xzBccqxmoWb4fYNLTfDPYEjN8OtI8E4RjlWOSqOVS4ejlXtFnQKT66klCc4TjlWs4yJ3b6hHRe7J3AcG7t1JBjHKMcqR8WxysfDsbK7hSNXUs6ulOWUZTU7jum5ksMTuOM40VzJHMq1ylFxrfIxca2KSzuF3cIGRxwLBMcp22oWHLt9Q4tj9wSOOHbrSDCOUc5VjopzlY+Hc1Xlj2OR4DilXs2y6XdQHFcjwHH1LOAY5WPlqPhY+Xj4WOWlnd0NnsNjWSIwTllZM8DY7RpKFLvl+YHYrSLBGEZ5WjkqnlY+Hp6W1Ss8h8YywXDK1ZoZw/QjY7c8bwwne1yM8rZyVLytfDy8reIrRYWrG1YIhFPm1ixvje2eoX1nbBfn+MbYriHB+EX5Wzkq/lY+Hv6W2Sk8XbBK8Juyt2bFL70Hdopzxm+i/W8e5W3lqHhb+Zh4W68UVa7+VyP4TVlbs+FXDeZ/Ve7+V022/82jfK08FV8rHw9fy+wUnv43R/CbsrVmxW8g/6ty979qwv0vytPKU/G08vHwtNbKpFsq2xyX8st5guCUpzUDgod9Q4nh4Qn8UDysI8E4RnlaeRqelpiNh6dFOkXbqdzmiGMlu1JWUp7WbJ7Y7ht6X2yfwNUb23UkGMcoTytPw9MSszHtY7hb5TkcVgQC4pSkNctiRKtjaFciWqU5LkO0KkgwdlFuVp6GmyVm4+FmQZ9wHAorIsFuSsyaEbv0I2G7NF/sJnscjPKx8jR8LDEbDx9rZ7O0Vdja45h4R5EIfFNC1gzwHfYNJYKHJ/AD8bCOBOMY5WTlaThZYjYeTtbOK7slc3d2bjCWCYxTTtYsMHa6hhbFTnmOIHaqSDCGUU5WnoaTJWbj4WStl3c4Z4ZWFALilJU1A4iHfUOJ4uEJ/GA8rCPBOEa5WXkabpaYjYebVd5aL2zxdMUqQXHKzZqFHm33DC072i7OkRxt15BY/IpZlJuVp+Fmidl4uFmkUzjH0hoBcErOmg3AgWJptzxXCCc8lhazGD/LRDYFhuPhZwmivLRV2OE5r5UjIE4ZWjOAeNg3lCgensAPxsM6EoxjjKdlopsCx/HwtKBL9jah87jhOE9wnPK0ZtntzO0b2v3O3BM47njm1pFgHGM8LRPd03EsxMPT2tmuvLJU2K3yw7GaXSmrKU9rlglqt29oZ6jdEzhOUbt1JBjHGE/LRDcFjuPhacHrv+0Kx7GxKhAYp0ytGV8Xm10T4G2xWZ7vy2KzigRjGONrmcimwHBM+xfermwUbm1xxLBIMJwytmZJied0DW1GPKc8x4R4ThUJxjDG2zKRTYHhmHhbpa29wlaJI4YlguGUtjWLH3a6htYPO+U5+mGnigRjGONsmcimwHA8nK1NkWccLRP8pnytGfBrdgslds2y/HBrXj7BmMU4WiaSKTAbD0ercqvCeZ8WVSHATTlaM+3TUgm6T0slgn1aKknfp0XMYhwtE90UOI6Ho1V6eW+XM45VguOUpTUDjod9Q4nj4Qn8cDysI7k4FjCuloluChzHmEdrs/giRxxrBMcpWWvWTDxm3wTJxWOewDkbj1lHgnGM8rUEKr6WEA9fawv6hGcGADVHYJzStWaheThdQ8vycMpzJHk4VSQYwyhXS6DiagkxcbXMXuGYCUDNEwynVK2ZMUyfC8AtzxvDSc4HIAooT0ug4mmJMfG0zDf2Aj8Ma9mVspbStGbmdwgB+R0Cf36HkGgMoxwtgYqjJcbJ0RI5YlggGE45WjNjWAyIYZE/hsVEYxjlaAlUHC0xHo6W1SsSRwyLBMMpR2tmDEsBMSzxx7CUaAyjHC2BiqMlxsPRsjbO4RlLSwTDKUdr5k2W6GNptzzvbZaSHUujHC2BiqMlxsPRsjbf4IlhmWA45WnNvFFLIAyr/DGsJh3DKGdLoOJsibHtdUh6hed4WCEYTilbM2OYfjzslueN4WSPh1G+lkDF1xJj2++Q9ArP8bBKMJzStWbGMP142C3PG8OJHg+LKFdLoOJqifFwtczc/TxDaY1AOGVqzbrJA30k7RTnvM1DouNoEeVoiVQcLTEejpbZKTzD6BzBb0rRmhW/9FG0U5wzfhMdQ4soP0uk4meJ8fCzzP03ePrfPMFvSs+adaOWYP53jbv/XUu2/0W5WSIVN0uKh5tldgpH/5vLrpRzKTVrVvwG879r3P3vWrL9L8rLEql4WRINL4sZbNfK2/ANR9wKBLeR0bFCQTXGPYXtTqDeUtguz3NHYbuKBIMUJV6JVMQriYZ4xW5+ebOwyxGhIkFoZGSrxUSo1QO0c8hmYY4TyOb1EwxMlE0lUrGppBE2lajWChtsgl/rUhHGvhvdj+z0o0ZnzHGv2cjzFvbaSqVR71TcogwqkYpBJclx4Zb1nJOD20jj3qThlsV0E0vcJnu2CWVNiVSsKUmJCbfM3/U4uD1L80ysccvkNQ9D3Cb8LQ/KlBKpmFKSGhduOfnbM/V+hzluWdArWOI20f5WQtlRIhU7StJiwC0ffqMD3LNErGAJXIbURkbQPQPMRgllRklUzCgpFxt2OQXLZ4rUyB67TJYWMMVuouNlCWVFSVSsKCkfG3Z5BcxnaU0Be+wyWdrHFLvJjplRRpRExYiSs/Fgl8P6ege7Z2lNH2Psslpazw67SV9ZL6FsKImKDSULMWCXT34bB7tnaU09S+wyTG3DCLtnILONhJKkJCqSlCzGhl1e492zlNOGPXaZpJZjit1kj3dRHpVExaOS4+BR8cnv6mD3LOWUY49dJqldmWI32TEzyqWSqLhU8giXSlBvFWrL5Far9ds7O2PYvd1u9ntBQWxd0waxc+nl9Zy6JGRtLO9t70E3ciItb4srdxYQy0EgbLbxBAgPe3QcwlZPeDDsYtpC8E27d+DjJCjbxcaBbCsXFsj29UdgPOgc1TvH0F69m8WrG1dfvLq7et375TSgrzePjHYP2nuvVN0p7Rb2bu+au4s6X5vPfH2383ABzQJK1ZKoqFqyEp9ZyEdkFqSVOwsYnkdpFvKpWUigWUCZYBIVE0zGcmaxtQuji5tiMQzyyp0FnHNjut4pVsvAau1TahoCmgYZJZtJVGQzWRuPGF7armxUqi9zCBjsKy/bjx5LS2A+oAuC+ZnG+9OiArfXpg73LUhPG+PbJ3GLAOzr+8K8UNyoXr17t3V9Xz8x/97rXm0MDvrmsfnB+eKo2bY+9IwG+XBklziyChzZvx9d75DeXjoxdOtbp7D5xaFuXh/+QOn7Tr33ncvdt6933znV+t08yzqnZX5ddc6s2ipXXZ2rjtJVV+uqc/mqffmqc/mqrVHVUak6vLJ7ac+1hxd3z3ROndVQkgfqdrW0tFHZvpMUQ4ky+2QqZp+M5TxjailHQ6jUVHLMrRKZrWQVE6XGMjWWURtLlEopU1Ep5TwSVVZqe+t8okrryjxM5c0ytLne6DcfGLV7hnHWVutPDTqdTk2DztSOpnYUtaMorVWmorUqCK2VqR0deVUfsR2ViB1dwJl8Li/rI7OjjF7Pp3Y0taNR21GUYixTUYwVLOEiU0N6avAerSWViSVdwFcfnMb2UZnSdGyf2tJFtaUo5VumonwrXsq3BdelnW6zYSzv7JaLJcecrhu9Rrd5bJk7+DnTOcj07xmZnnnKMmlJTwnL+t7MLmsK+Q+wC4eWKb75/PXWXWKlzM9URtnoD46XR1Qrt8EsmwouO2NJ3lZZIVaZwwIuy5TiJnnYgMOvGNjom1aeWOvziLWGlva11d4emGCw7cdm3Fw7HRXMXjtnjRlsC49LdnX+Vnu9sFcYt9i1vt4f9G7Wjo1G86BpkJayvyFP+oE+aPUBrs7HEfvuKORr4J+/fnh09fnr9w+JqCz1O+2r8MQTUbWk9cf6nsi2McGQgXEYOfaaNdPYeA49Nu72VnnPaRrExN2ELSPcA8zanW61oa0zH5v6tq0tPEpXq9uV0lXipollvQr/28+WW8hjH4VY7CNKq5epaPWKxNE+craM9uiQt2VUiWXksCx9smVMiE20uyigTbTPmh+baCuU2sTFsYnocgWZarmCIvOMGVXOVtEZ6PE2ixoxixwy7UwJGNWEGEanlwJaRue0+TGNjkapbVwc24iu2ZCp1mwoSHrd09xs2jc4Lu96r7ZdsVnXlfJ7b5f5T0LmsyvlfGRJdWnN1JoejnE97b3NJMI19MEEurXTL/58a68BcEqPGIXTT+uefmi3kPdRHX6L0d+y1mPofdFo2Xa7iuHZ06+PMUYE6/reCXizU5DLlx6Rh6qtt5A6Tv2E38gUsI3dm6fu7Kgm10/VF0Q3vBFodPO0i0cZYZpqzkOw52ejzB9marLhg+EJvMx5fyh7s9jp9d++Jq+sCQ4fxrS4mwSMRhcMv43Oke+ghOdqo8VO/bC60Woem+rb3tMuefrr1cKg39nodI/0/s1HLVOT4TdbHfCAnhKrax24/0KXOLV9uMGRY/Nad5r7xFratQ2/WLUrPWlZi+Kbfc8R3GKzfegel4nn7VqXNh9/z+Fq1egSFdv7RcP0U/3ugNRz6ksnhth+cRg8XB/pU9q+n+mRHIIW7fsxD/B84Xlh5fny8xL+KFi3ONdPghjFkyDF+iSgXBSaKCXIk1BQV8qCurCPgRzFY6DE+hhgr9JpXqRL05xBQVAWuu/VKPpei7XvsVd/NC/+5EAmQBRWylJ2YZ+DXBTPQT7W5wB7xUHzgkMJ8hxUhZXb8sI+BUI0sWG8wSE2rUszqatOeA6sfExORJjzGR0swhMQSUwoxBsUYpNXNFNX2vRoIL9SFhc3GhAiCQWFeGNBLK8ETVaJXMDBoSSDLZAXd3goRBIcCvFGhwKWS4Amk0A+4OMgq/A4qIsbIgqRxIhCvEGigE0bCjTzhsKkiUPsgVAleCDc/b0W74EQI4kWxXijRQGdS6SaTJw0mzhM45OAoFGMJGgU4w0aBWwqUaCZSxQmTSZ6HoRteBDuPL+4w0cxkvBRjDd8FLC5RIFmMlGYNJuIeYicZRi0xX0gIokgxZgjSGyCUaCZYRQCTTHCA5GHByK/uDGkGEkMKUYSQ1aavb7vQwE/zvQG2jzbeg3tfLQYStZMpPNxlfTY9sFBzzA5S8ODUyqDGkHVnunl6SS1JVRtgbHaM73pm6S2hqotMlZ7pjdTk9TOompLjNWe6aXKJLVlVG2ZsdozvQOYpLaIqq0wVnumKetJaguo2ipjtWeaZ52kdg5VW2Os9kwThJPUVlG1c4zVnm0my1FWQPTOR2K4Z5xycbQVsccbf76Zaz7b3MBEzXGDwtrrzDiYnag57uZZO54Zh18TNY/G98w4TpioOR4RsnY/AuY2BWq/iWqO20TWHkjAPKdA7TpRzfG4kLUTEjDnKVB7T1Rz3H0y90OY/xSoHSiqOe6J8qxHPpgHFahdKKa5iIfjAvNBG5rpldqJSpjq0ThREU27SO1EZUxz3Iky1xwdclI7UVRz3Imydv8ivntpKM1xJ8ra/Yt4Io9QmuNOlLX7F9El9tROFNUcd6Ks3b+ILoSldqKo5rgTZe3+RXSZGrUTRTWPZgwqorufUDtRVHPcibJ2/xK6OQO1E8U0l3Anytr9S5gPlah9qIJpHo0PlTAfKlH7UFTzaAaiEuZDJWofimoezUAU3QF8+gbgjroqpjnuiZg/LZgPnb798UTNcU/E/GnBfOj0zV8nao57IuZPC+ZDp299OVFz3BOxjlvQ7fmm7843UXPcE7GOW9AdxKZvIDZJcxn3RKzjFnSDo+n7G03UHPdErOMWdMeR6RuOTNQc90Ss4xY0/f/07P8TNcc9Eeu4BU24PT3f9kTN8dEc82kLNMft9BS3E1X3caKsvSiaUnJ6RsmJquNeVGD+zhlzo9OTvU1UHXejAms/iiZlmp6TaaLquB8VWDtSNGfK9JQpE1X3eUPH2pPKmCeVQ3lSxWdilLUrVTBXKodypYrPoI61L1UwX6qE8qWKz8woa2eqYM5UCeVMFR8aEWtvqmDeVAnlTRXcm4qsvamCeVMllDdVcG8qsvamCuZNlVDeVPEZk7L2pgpKKgrlTRUf7hlzFhfmTZVQ3lTBvanI2psqmDdVQnlTBfemImtvqmDeVAnlTVXcm4qsvamKeVMllDdVcW8qsvamKuZN1VDeVPWZI2XtTVXMm6qhvKnq86KRtTdVMW+qhvKmqs+bRtbeVMW8qRrKm6q4N5VYe1MV86ZqKG+q4t5UYu1NVcybqqG8qeozxcvam6ooTTeUN1Vxbyox50Vj3lQN5U1V3JtKrL2pinlTNZQ31Xw49Ky9qYZ5UzWUN9Vwbyqx9qYa5k21UN5Uw72pxNqbapg31UJ5U83nlSNrb6ph3lQL5U01H/Ira2+qYd5UC+VNNR/iDmtvqmHeVAvlTTXcm8qsvamGeVMtlDfVcG8qs/amGuZNtVDeVPN5Y8ram2rowpdQ3lTDvanMfKUR5k21UN40h3tTmflqI8ybaqG8aQ73pjJrb5rDvGkulDfN4d5UZu1Nc5g3zYXypjncm8qsvWkO86a5UN40h3tThbU3zWHeNBfKm+Z81pKw9qY5zJvmQnnTnA8PlrU3zWHeNBfKm+Zwb6qw9qY5zJvmQnnTHO5NFdbeNId501wob5rzISCx9qY5dClpKG+ax72pwtqb5jFvmgvlTfO4N1WYr9/FvGk+lDfN+6zzZu1N85g3zYfypnncmyqsvWke86b5UN40j3tTlbU3zWPeNB/Km+Zxb6qy9qZ5zJvmQ3nTvM/STNbeNI9503wob5r3WVbC2pvmMW+aD+VN87g3VVl70zzmTfOhvGke96Yqa2+ax7xpPpQ3FbI+hF7mC5GzaHaGUP5UyPqk8WC+FjmLp2gI5VKFLO5TVfZ5MdA0DdlQXlXI4m5VZe1WSUWo9qEcq5DFPavG2rOSilDtqX2rhmofzToZUg+qPLV3xZWPZqkMqQdVntq/4spHs1qG1IMqT+1hceWjWTBD6kGVp/axuPLRrJkh9aDKU3tZVHkhmmUzApoCybylMMpHs3JGwPMg0SdCyqHKR5RPyCcVErWPRZX3sfPMrQ2eDYk+HRKuvM8rPubKox6WPiMSrrzPtCRz5VEPS58UCVfeZyjFXHnUw9LnRcKVx+08e2uDelj61Ei4tcHtPPOIHk+ORJ8dCVcet/PMA3o8PxJ9giRM+Yhy9Qh4hiT6FElYlkHBJ3Mccx+F5kgS6JMk5VHlfVZKMlcedbD0eZJw5X1WdzBXHk83SO1gceV9GKnMlUcdLH22JFx5HxYNc+VRB0ufMAlX3ufNH3PlUQdLnzMJV95ntpK58qiDpU+bhCrvk06OeXSAJk4S6DMn4crjTop5dIDmThLokyfhyuMDKebRAZo+SaDPn4Qr77N2kvl0H5pCSaDPoYRr7+NimftYNI2SQJ9HCdfeZ7KSfUpf1MnS51LCtfdJScDcy6LplAT6fEq49j5ZCZi7WTSlkkCfU0lAk7T75Jpj/9yjfpY+r5KP9j7LKZlrjzpa+txKuPY+uTjYP/eop6XPr+SjfUThJZpiSaDPsYRr75PZinmIhqZZEujzLPloH02eRQFNtSTQ51ryeXKiybUooOmWBPp8Sz7a+8yDMA900JxLAn3SJR/1fdJzMLeZaN4lgT7xko/6PmEm+z0A8FT6Id2tX9Ir5uNaNP+SQJ+AyUd9n0CTvdlEHS59EiYf9SOaVEDTMAn0eZh8tI9o2h7NxCTQp2LCtfdLxsQ80kSzMQn06Zh81Pex+ux38EBdLn1KJgGd//ZLysRce9Tl0mdl8tE+otl7NC+TQJ+YyUf7aNLWC2hqJoE+N5OP9tGkrhfQ7EwCfXomH+2jSV8voAmaBPoMTT7aR5PCXkBzNAn0SZp8tI8mjb2ApmkS6PM0+Wgf0RALzdQk0KdqwrX3SdbEfIiFJmsS6LM1+Wgf1RALTdgk0Gds8lHfx9ky97Zo0iaBPmuTj/o+Qyzm7hZN3CTQZ27yUd9niMXc36LJmwT67E0+6vsMsZg7XDSBk0CfwclHfZ/JfPb7xaEelz6Lk4/6PrP5zF0umshJoM/k5KO+z2w+c5+LJnMS6LM5+ajvk2uYudNFEzoJ9BmdcPV9cjoxTx8roEmdBPqsTj7q+2RJZO510cROAn1mJx/1fWjIzL0umtxJoM/u5KO+zxiXuddFEzwJ9BmefNT3yT/M3OuiSZ4E+ixPPur7sNSYe1000ZNAn+nJR32fBT/MvS6a7Emgz/bko75PLmL2W7WiXpc+45OP+j75iJl7XTTpk0Cf9clHfZ+X6My9Lpr4SaDP/ISr75P7iXmaWQFN/iTQZ3/yUd8nmyJzr4smgBLoM0D5qO+TUZG510WTQAn0WaB81PfJqsjc66KJoAT6TFA+6vtMLTP3umgyKIE+G5SP+j6Lr5h7XTQhlECfEcpHfR/+DnOviyaFEuizQvmo77PQlrnXRRNDCfSZoXzU98lbzH6XdNTr0meH8lHfJ3cxc6+LJogS6DNE4er75Ihino5WQJNECfRZonzU98m6yNzroomiBPpMUT7q+2ReZO510WRRAn22KB/1fbIvMve6aMIogT5jlI/6PvmMmXtdNGmUQJ81ykd9nze6zL0umjhKoM8c5aO+z6Jn5l4XTR4l0GeP8lHfhzbL3OuiCaQE+gxSPur7JLhg7nXRJFICfRYpH/V9chwz97poIimBPpMUqr7ok0qKedpaEU0lJdDnkvJR3yc7I2uvK6LJpET6ZFI+6vtkaGTtdUU0m5RIn03KR32fLI2sva6IppMS6dNJ+ajvk/eYtdcV0XxSIn0+KR/1fXIfs/a6IppRSqTPKOWjvg+RirXXFdGcUiJ9Tikf9X2SjbD2uiKaVUqkzyrlo74PcZm11xXRvFIifV4pH/V9Ekux9roimllKpM8shavvk3KEeXpbEc0tJdLnlvJR3yeFI3Ovi2aXEumzS/mo75PDkbnXRfNLifT5pXzU90niyNzrohmmRPoMUz7q++RHZu510RxTIn2OKR/1fXIkM/e6aJYpkT7LlI/6PnmSmXtdNM+USJ9nykd9H/4yc6+LZpoS6TNN+ajvs0aUuddFc02J9LmmfNT3yULC3Oui2aZE+mxTuPo+eUiYZ78V0YRTYoCEU7j6PikdmXtdNOWUSJ9yykd93OtqzL0umnRKpE865aM+7nU15l4XTTsl0qed8lHfJ3cyc6+LJp4S6RNP+aiPe12NuddFU0+J9KmnfNTHva7G3OuiyadE+uRTPurjXldj7nXR9FMiffopH/V9lg0x97poAiqRPgGVj/o+q3SZe100BZVIn4IKV1/yyf7F3OuiSahE+iRUPur75P9i7nXRLFQifRYqH/Vxr5tj7nXRNFQifRoqLOO/KOFOl4P2qNOlT0OFa4/7XA6PDupz6dNQ4dr7uFz2uEVdLn0aKlx7H4/L3GiiaahE+jRUuPY+Dpe5x0LTUIn0aahw7X38LfNwAU1DJdKnocK193G3zGM1NA2VSJ+GCtXeJxMS+0AZTUMl0qehwrX3GeIyH6WgaahE+jRUuPY+I1zmQ0Q0DZVIn4YK195ngMvc16JZqMQAWahEVP1oUlqLaBIqMUASKlz7aHJai2gOKjFADipc+2jSDopoCioxQAoqCdXeZ40oc+1RXxsgAxWqvU8WJPZPDuprA2SgwrX3WavCXHvU1wbIQIVr70OaZa09moBKDJCACtfeh73DXHvU1wbIP4Vr7/Makbn2qK8NkH9KRrUPtRlcod/vNu8O+saY6u4vWJtPbXGiDLEmoJJ7nZsv6a2BsXp9+MVqsdMaHLWhpP1pddPQ95vtQ6esc7haPmx3usb+zQO91SPfO4du23jzotX6Jy0DvrE+2DfvqZb2zlF+OcWdC6fvfEs/or1xqyj1fQtj9y2Ev280qqK4b5G6x4XwPT5+52L4O8cisqnxGNFAOn3nt9vNfg+7c3H8zu2yIe5cCn/nWDQ3NZYjGsin77zW1/sD9Nal8Vt3Coe4dzn8vWOx4NRIkGigjD/v3SZo54d3GXvsrVMyoYGvhG8ILKycGlRao8DRhiivC9j9K+P3v333Q0ajnzFPCHHzavibx6LSqTFp2dw08fTNi9jNqxNuXgx181r4m8eC2qkhbdncjGv05ouddl9vto0u1gTaeBN4yodogVz4FkD5jVPj4rK584JPE9T3To5RO5Cb0A72SSEaI8+gMfANr2lin7Gwj1/wI44HPwyiPp+tPGnufSzw4xkAIXfPIPbD9wKlif6EsfCPZxCE3D2D+A/fTJQmAhTGQkC+gRBy/wyiQHw/Upo4UBgLBCMMhpDGYBAW4vub0gSGwlhkyDkgQhqAQTiI75FKExAKSETINShCGoBBSIjvs0oTFApjUWEUgRHSCgxiQ3zDVproUPAPD2eKjTIBYyOkPRhEivgmsDShojAWK/ILjqTxe2cQGOKEXprAUKSfD2QQHI3fvchiQhBfhUNz92OhIc/gCLl7BqGhD52Y5u7HQkO+wRFy/wyCQ5yPTBMcimPBYYTBEdIYDCJFnN1MEymKY5Ei5+AIaQAG0SHOj6aJDkUkOuQaHCENwCA6xBnWNNGhOBYdRhEcIa3AIETEido0IaLoHyJGEhwh7cEgWMSZ3zTBojgWLPILjuTxe2cQGOK0cZrAUBwLDHkGR8jdMwgNUdb5dNI5PIljoSHP4Gj87iUGoSFKWp/OWYe7HwsN+QZHyP2zeGeMBYfTWe9w/8hr48iCI6QxGESKKIt+OokeGmMsUuQcHCENwCA6RIn403n40ABIdMg1OEIagEF0iHL5p1P5oQHGosMogiOkFRiEiOiagOlLAqAV/EPESIIjpD0YBIvoKoPpiwygPcaCRX7BkTJ+7wwCQ3SNwvQlCnDvY4Ehz+AIuXsGoSG6xmH6Ege4+7HQkGdwhNw9g9AQXSMxfYkE4HAsNOQbHI3fv8wgOERXWUxfZAH3j7xSjiw4QhqDQaSILtqYvmYDGmMsUuQcHCENwIJkiEWH05d9QAMg0SHX4AhpAAbRIbp0ZPrKEWiAsegwiuAIaQUGISK6BGX6ChRoBf8QMZLgCGkPBsEiuqhl+poWaI+xYJFfcKSO3zuDwBBdEjN9RQzc+1hgyDM4Qu6eQWiILqmZvqIG7n4sNOQZHCF3zyA0RJfkTF+RA3c/FhryDY6Q+2cQHKKLeqav6QE7hLxSjiw4Gm8MhUGkiK4Rmr5ECBpjLFLkHBwhDcAgOkS3uZ++yz00ABIdcg2OkAZgEB0qWHSo0ESHylh0GEVwhLQCi+UoWIio0ISIin+IGElwhLQHg2BRQdeoUC1SGQsW+QVH2vi9MwgMFSwwVGgCQ2UsMOQZHCF3zyA0VLDQUKEJDZWx0JBncITcPYPQUMFCQ4UmNFTGQkO+wRFy/wyCQxULDhWa4FBBXilHFhwhjcEgUlSxSFGliRTVsUiRc3A0
